Workbook

Sheet 摘要
A1: 一頁摘要 — 結論、與市場的差異、現價隱含什麼、驗證點（全部依輸入連動）
A2: ="模型端＝目前情境：" & CHOOSE(輸入與假設!$C$5,"保守 4.2 GW","基準 5.6 GW","積極 8 GW") & "（預設＝基準）；共識＝data/consensus_crwv_20260925.json（2026-09-25）" -> 模型端＝目前情境：基準 5.6 GW（預設＝基準）；共識＝data/consensus_crwv_20260925.json（2026-09-25）
A4: 1｜結論
A5: 結論｜評等代碼（1＝買進、0＝中立、−1＝賣出） | C5: =損益與評價!C71 -> -1
A6: 結論｜評等 | C6: =CHOOSE(C5+2,"賣出","中立","買進") -> 賣出
A7: 結論｜點位（加權目標價） | B7: US$ | C7: =損益與評價!C63 -> 45.50115
A8: 結論｜現價 | B8: US$ | C8: =輸入與假設!$C$88 -> 90.13
A9: 結論｜空間 | B9: % | C9: =C7/C8-1 -> -0.49516088
A10: 結論｜情境區間（下緣／上緣） | B10: US$ | C10: =損益與評價!C76 -> 30.953266 | D10: =損益與評價!D76 -> 69.741657
A11: 結論｜方法區間（下緣／上緣） | B11: US$ | C11: =損益與評價!C78 -> 29.475228 | D11: =損益與評價!D78 -> 45.50115
A12: 結論｜賣出門檻價 | B12: US$ | C12: =損益與評價!$C$72 -> 76.6105
A13: 結論｜點位 − 賣出門檻 | B13: US$ | C13: =C7-C12 -> -31.10935
A14: 結論｜結論句 | C14: =C6&"：點位 $"&TEXT(C7,"0.0")&"，較現價 $"&TEXT(C8,"0.00")&" "&IF(C9>=0,"高","低")&" "&TEXT(ABS(C9)*100,"0")&"%；情境區間 $"&TEXT(C10,"0.0")&"–$"&TEXT(D10,"0.0")&"，方法區間 $"&TEXT(C11,"0.0")&"–$"&TEXT(D11,"0.0")&"；點位"&IF(C13<0,"低於","高於")&"賣出門檻 $"&TEXT(C12,"0.0")&" 達 $"&TEXT(ABS(C13),"0.0")&"。" -> 賣出：點位 $45.5，較現價 $90.13 低 50%；情境區間 $31.0–$69.7，方法區間 $29.5–$45.5；點位低於賣出門檻 $76.6 達 $31.1。
A15: 結論｜情境判斷句 | C15: =損益與評價!C84 -> 情境區間上緣 $69.7 低於現價 $90.13：賣出在三個擴張情境下都成立。
A16: 2｜與市場的差異（模型：目前情境 vs 共識；FY26–FY28）
A17: 差異｜營收｜模型 | B17: US$bn | C17: =損益與評價!C16 -> 13.066 | D17: =損益與評價!D16 -> 26.1275 | E17: =損益與評價!E16 -> 36.669415
A18: 差異｜營收｜共識 | B18: US$bn | C18: =輸入與假設!$C$142 -> 12.882 | D18: =輸入與假設!$D$142 -> 26.376 | E18: =輸入與假設!$E$142 -> 42.55
A19: 差異｜營收｜差距 | B19: % | C19: =C17/C18-1 -> 0.014283496 | D19: =D17/D18-1 -> -0.0094214437 | E19: =E17/E18-1 -> -0.1382041
A20: 差異｜調整後 EBITDA｜模型 | B20: US$bn | C20: =輸入與假設!$C$131+損益與評價!C11 -> 7.63067 | D20: =損益與評價!D19 -> 15.807137 | E20: =損益與評價!E19 -> 22.735038
A21: 差異｜調整後 EBITDA｜共識 | B21: US$bn | C21: =輸入與假設!$C$143 -> 7.574 | D21: =輸入與假設!$D$143 -> 16.656 | E21: =輸入與假設!$E$143 -> 28.857
A22: 差異｜調整後 EBITDA｜差距 | B22: % | C22: =C20/C21-1 -> 0.0074821759 | D22: =D20/D21-1 -> -0.050964367 | E22: =E20/E21-1 -> -0.21214826
A23: 差異｜調整後 EBITDA｜差距（金額） | B23: US$bn | C23: =C20-C21 -> 0.05667 | D23: =D20-D21 -> -0.8488625 | E23: =E20-E21 -> -6.1219624
A24: 差異｜EBITDA 率｜模型 | B24: % | C24: =C20/C17 -> 0.58400964 | D24: =D20/D17 -> 0.605 | E24: =E20/E17 -> 0.62
A25: 差異｜EBITDA 率｜共識 | B25: % | C25: =輸入與假設!$C$144 -> 0.588 | D25: =輸入與假設!$D$144 -> 0.632 | E25: =輸入與假設!$E$144 -> 0.678
A26: 差異｜EBITDA 率｜差距（百分點） | B26: pt | C26: =C24-C25 -> -0.0039903567 | D26: =D24-D25 -> -0.027 | E26: =E24-E25 -> -0.058
A27: 差異｜CapEx（毛額）｜模型 | B27: US$bn | C27: =輸入與假設!$C$122+輸入與假設!C$63 -> 36.975 | D27: =輸入與假設!D$63 -> 38.335 | E27: =輸入與假設!E$63 -> 29.41
A28: 差異｜CapEx（毛額）｜共識 | B28: US$bn | C28: =輸入與假設!$C$145 -> 35.953 | D28: =輸入與假設!$D$145 -> 46.476 | E28: =輸入與假設!$E$145 -> 50.129
A29: 差異｜CapEx（毛額）｜差距 | B29: % | C29: =C27/C28-1 -> 0.028426001 | D29: =D27/D28-1 -> -0.17516568 | E29: =E27/E28-1 -> -0.41331365
A30: 差異｜淨負債｜模型 | B30: US$bn | C30: =收支與融資!C135 -> 45.392496 | D30: =收支與融資!D135 -> 71.885337 | E30: =收支與融資!E135 -> 84.30991
A31: 差異｜淨負債｜共識 | B31: US$bn | C31: =輸入與假設!$C$146 -> 46.442 | D31: =輸入與假設!$D$146 -> 74.707 | E31: =輸入與假設!$E$146 -> 96.039
A32: 差異｜淨負債｜差距 | B32: % | C32: =C30/C31-1 -> -0.022598169 | D32: =D30/D31-1 -> -0.037769723 | E32: =E30/E31-1 -> -0.12212841
A33: 差異｜淨負債｜差距（金額） | B33: US$bn | C33: =C30-C31 -> -1.0495042 | D33: =D30-D31 -> -2.8216627 | E33: =E30-E31 -> -11.72909
A34: 差異｜分歧項目（超過門檻者） | C34: =MID(IF(ABS(C19)>輸入與假設!$C$150,"、營收 "&IF(C19<0,"−","+")&TEXT(ABS(C19)*100,"0.0")&"%","")&IF(ABS(C22)>輸入與假設!$C$150,"、EBITDA "&IF(C23<0,"−","+")&"$"&TEXT(ABS(C23),"#,##0.00")&"bn"&"／"&IF(C26<0,"−","+")&TEXT(ABS(C26)*100,"0.0")&"pt","")&IF(ABS(C29)>輸入與假設!$C$150,"、CapEx "&IF(C29<0,"−","+")&TEXT(ABS(C29)*100,"0.0")&"%",""),2,999) | D34: =MID(IF(ABS(D19)>輸入與假設!$C$150,"、營收 "&IF(D19<0,"−","+")&TEXT(ABS(D19)*100,"0.0")&"%","")&IF(ABS(D22)>輸入與假設!$C$150,"、EBITDA "&IF(D23<0,"−","+")&"$"&TEXT(ABS(D23),"#,##0.00")&"bn"&"／"&IF(D26<0,"−","+")&TEXT(ABS(D26)*100,"0.0")&"pt","")&IF(ABS(D29)>輸入與假設!$C$150,"、CapEx "&IF(D29<0,"−","+")&TEXT(ABS(D29)*100,"0.0")&"%",""),2,999) -> EBITDA −$0.85bn／−2.7pt、CapEx −17.5% | E34: =MID(IF(ABS(E19)>輸入與假設!$C$150,"、營收 "&IF(E19<0,"−","+")&TEXT(ABS(E19)*100,"0.0")&"%","")&IF(ABS(E22)>輸入與假設!$C$150,"、EBITDA "&IF(E23<0,"−","+")&"$"&TEXT(ABS(E23),"#,##0.00")&"bn"&"／"&IF(E26<0,"−","+")&TEXT(ABS(E26)*100,"0.0")&"pt","")&IF(ABS(E29)>輸入與假設!$C$150,"、CapEx "&IF(E29<0,"−","+")&TEXT(ABS(E29)*100,"0.0")&"%",""),2,999) -> 營收 −13.8%、EBITDA −$6.12bn／−5.8pt、CapEx −41.3%
A35: 差異｜分歧起始年（1＝FY26…3＝FY28；0＝無） | C35: =IF(C34<>"",1,IF(D34<>"",2,IF(E34<>"",3,0))) -> 2
A36: 差異｜判斷句 | C36: =CHOOSE(C35+1,"FY26–FY28 營收、EBITDA、CapEx 與共識差距皆在 "&IF(ROUND(ABS(輸入與假設!$C$150)*100,4)=INT(ROUND(ABS(輸入與假設!$C$150)*100,4)),TEXT(ROUND(ABS(輸入與假設!$C$150)*100,4),"0"),TEXT(ROUND(ABS(輸入與假設!$C$150)*100,4),"0.0"))&"%"&" 以內。","分歧始於 FY26（"&C34&"）"&"；FY27 "&IF(D34="","回到 "&IF(ROUND(ABS(輸入與假設!$C$150)*100,4)=INT(ROUND(ABS(輸入與假設!$C$150)*100,4)),TEXT(ROUND(ABS(輸入與假設!$C$150)*100,4),"0"),TEXT(ROUND(ABS(輸入與假設!$C$150)*100,4),"0.0"))&"%"&" 以內",D34)&"；FY28 "&IF(E34="","回到 "&IF(ROUND(ABS(輸入與假設!$C$150)*100,4)=INT(ROUND(ABS(輸入與假設!$C$150)*100,4)),TEXT(ROUND(ABS(輸入與假設!$C$150)*100,4),"0"),TEXT(ROUND(ABS(輸入與假設!$C$150)*100,4),"0.0"))&"%"&" 以內",E34)&"。","FY26 營收、EBITDA、CapEx 與共識差距在 "&IF(ROUND(ABS(輸入與假設!$C$150)*100,4)=INT(ROUND(ABS(輸入與假設!$C$150)*100,4)),TEXT(ROUND(ABS(輸入與假設!$C$150)*100,4),"0"),TEXT(ROUND(ABS(輸入與假設!$C$150)*100,4),"0.0"))&"%"&" 以內；分歧始於 FY27（"&D34&"）"&"；FY28 "&IF(E34="","回到 "&IF(ROUND(ABS(輸入與假設!$C$150)*100,4)=INT(ROUND(ABS(輸入與假設!$C$150)*100,4)),TEXT(ROUND(ABS(輸入與假設!$C$150)*100,4),"0"),TEXT(ROUND(ABS(輸入與假設!$C$150)*100,4),"0.0"))&"%"&" 以內",E34)&"。","FY26–FY27 營收、EBITDA、CapEx 與共識差距在 "&IF(ROUND(ABS(輸入與假設!$C$150)*100,4)=INT(ROUND(ABS(輸入與假設!$C$150)*100,4)),TEXT(ROUND(ABS(輸入與假設!$C$150)*100,4),"0"),TEXT(ROUND(ABS(輸入與假設!$C$150)*100,4),"0.0"))&"%"&" 以內；分歧始於 FY28（"&E34&"）。") -> FY26 營收、EBITDA、CapEx 與共識差距在 5% 以內；分歧始於 FY27（EBITDA −$0.85bn／−2.7pt、CapEx −17.5%）；FY28 營收 −13.8%、EBITDA −$6.12bn／−5.8pt、CapEx −41.3%。
A37: 差異原因｜FY26｜淨負債 | C37: =IF(ABS(C32)>輸入與假設!$C$150,"觀點","") | D37: =IF(ABS(C32)>輸入與假設!$C$150,"淨負債隨 CapEx 與融資需求而定（模型 CapEx 差距 "&IF((C29)<0,"−","+")&TEXT(ABS((C29))*100,"#,##0.0")&"%"&"）；共識淨負債不含租賃、口徑未揭露","")
A38: 差異原因｜FY27｜EBITDA | C38: =IF(ABS(D26)>輸入與假設!$C$151,"觀點","") -> 觀點 | D38: =IF(ABS(D26)>輸入與假設!$C$151,"EBITDA 率 "&IF((D24)<0,"−","")&TEXT(ABS((D24))*100,"#,##0.0")&"%"&" 對共識 "&IF((D25)<0,"−","")&TEXT(ABS((D25))*100,"#,##0.0")&"%"&"：模型由 "&IF((輸入與假設!$C$32)<0,"−","")&TEXT(ABS((輸入與假設!$C$32))*100,"#,##0")&"%"&" 線性爬升至 FY30 穩態 "&IF((輸入與假設!$C$33)<0,"−","")&TEXT(ABS((輸入與假設!$C$33))*100,"#,##0")&"%"&"；營收差距 "&IF((D19)<0,"−","+")&TEXT(ABS((D19))*100,"#,##0.0")&"%","") -> EBITDA 率 60.5% 對共識 63.2%：模型由 59% 線性爬升至 FY30 穩態 65%；營收差距 −0.9%
A39: 差異原因｜FY27｜CapEx | C39: =IF(ABS(D29)>輸入與假設!$C$150,"觀點","") -> 觀點 | D39: =IF(ABS(D29)>輸入與假設!$C$150,"CapEx 依新增 MW 計算：新增 "&IF((輸入與假設!D$57)<0,"−","")&TEXT(ABS((輸入與假設!D$57)),"#,##0")&" MW × 每 MW $"&IF((輸入與假設!D$49)<0,"−","")&TEXT(ABS((輸入與假設!D$49)),"#,##0")&"m（含次年預建）；共識口徑未揭露","") -> CapEx 依新增 MW 計算：新增 1,250 MW × 每 MW $34m（含次年預建）；共識口徑未揭露
A40: 差異原因｜FY27｜淨負債 | C40: =IF(ABS(D32)>輸入與假設!$C$150,"觀點","") | D40: =IF(ABS(D32)>輸入與假設!$C$150,"淨負債隨 CapEx 與融資需求而定（模型 CapEx 差距 "&IF((D29)<0,"−","+")&TEXT(ABS((D29))*100,"#,##0.0")&"%"&"）；共識淨負債不含租賃、口徑未揭露","")
A41: 差異原因｜FY28｜營收 | C41: =IF(ABS(E19)>輸入與假設!$C$150,"觀點","") -> 觀點 | D41: =IF(ABS(E19)>輸入與假設!$C$150,"營收由模型 MW 路徑決定：FY28 年底 Accepted "&IF((輸入與假設!E$23)<0,"−","")&TEXT(ABS((輸入與假設!E$23)),"#,##0")&" MW（目前情境）；共識未揭露 MW 假設","") -> 營收由模型 MW 路徑決定：FY28 年底 Accepted 4,000 MW（目前情境）；共識未揭露 MW 假設
...

Sheet 輸入與假設
A1: 輸入（依類別排序；點左側 ＋／− 展開或收合。藍字可改；黃底為最關鍵假設）
A2: A 情境 → B 產能與收入 → C 利潤率 → D 支出（CapEx／折舊／租賃／JV）→ E 融資 → F 評價 → G 參考：1H26 實際 → H 情境區間運算表 → I 市場共識 → J 季度追蹤輸入。灰底『▸』為明細子區，預設收合
A4: A｜情境與規模（管理層擴張力道）
A5: 情境選擇（1＝保守 4.2 GW、2＝基準 5.6 GW、3＝積極 8 GW） | C5: 2 | D5: =CHOOSE(C5,"保守 4.2 GW","基準 5.6 GW","積極 8 GW") -> 基準 5.6 GW
A6: 保守 4.2 GW | B6: MW | C6: 1850 | D6: 3100 | E6: 3800 | F6: 4200 | G6: 4200 | I6: 0
A7: 基準 5.6 GW | B7: MW | C7: 1850 | D7: 3100 | E7: 4000 | F7: 4800 | G7: 5600 | I7: 500
A8: 積極 8 GW | B8: MW | C8: 1850 | D8: 3100 | E8: 4600 | F8: 6300 | G8: 8000 | I8: 1000
A9: Billable／Accepted 爬坡比例 | B9: % | C9: 0.91891892 | D9: 0.93548387 | E9: 0.93478261 | F9: 0.93650794 | G9: 0.9375
A10: 表外現金租金（積極路徑） | B10: US$bn | C10: 0.3 | D10: 1.6 | E10: 3 | F10: 4 | G10: 4.6
A11: 表外租金起算 MW | B11: MW | C11: 1500
A12: B｜產能與收入（RPO、MW、利用率、單價、簽約、信用）
A13: 6/30 RPO | B13: US$bn | C13: 103.7
A14: Q3 初新增承諾 | B14: US$bn | C14: 25
A15: 五期認列比例（至 2030 末） | B15: % | C15: 0.84
A16: RPO 桶權重合計 | B16: % | C16: 0.84
A17: 2025-12-31 主動電力 | B17: MW | C17: 850
A18: 6/30 Billable MW | B18: MW | C18: 1350
A19: 收入用平均在役 MW（1=是） | C19: 1
A20: 每 MW 年收入倍數（整體） | B20: % | C20: 1
A21: 模型期長度（年） | C21: 0.5 | D21: 1 | E21: 1 | F21: 1 | G21: 1
A22: RPO 桶權重 | B22: % | C22: 0.1025 | D22: 0.205 | E22: 0.2 | F22: 0.195 | G22: 0.1375 | H22: =SUM(C22:G22) -> 0.84
A23: Accepted MW（期末主動電力） | B23: MW | C23: =CHOOSE(輸入與假設!$C$5,C6,C7,C8) -> 1850 | D23: =CHOOSE(輸入與假設!$C$5,D6,D7,D8) -> 3100 | E23: =CHOOSE(輸入與假設!$C$5,E6,E7,E8) -> 4000 | F23: =CHOOSE(輸入與假設!$C$5,F6,F7,F8) -> 4800 | G23: =CHOOSE(輸入與假設!$C$5,G6,G7,G8) -> 5600
A24: Billable MW | B24: MW | C24: =ROUND(C23*C9,0) -> 1700 | D24: =ROUND(D23*D9,0) -> 2900 | E24: =ROUND(E23*E9,0) -> 3739 | F24: =ROUND(F23*F9,0) -> 4495 | G24: =ROUND(G23*G9,0) -> 5250
A25: 利用率 | B25: % | C25: 0.95 | D25: 0.95 | E25: 0.94 | F25: 0.93 | G25: 0.92
A26: 每 MW 年收入 | B26: US$bn/MW | C26: 0.0112 | D26: 0.0115 | E26: 0.0115 | F26: 0.011 | G26: 0.0105
A27: 新產能簽約率 | B27: % | C27: 1 | D27: 1 | E27: 0.9 | F27: 0.85 | G27: 0.8
A28: 客戶違約率 | B28: % | C28: 0.005 | D28: 0.01 | E28: 0.015 | F28: 0.02 | G28: 0.025
A29: 回收率 | B29: % | C29: 0.5 | D29: 0.5 | E29: 0.5 | F29: 0.5 | G29: 0.5
A30: 非算力服務營收 | B30: US$bn | C30: 0.3 | D30: 1 | E30: 1.8 | F30: 2.8 | G30: 3.8
A31: C｜利潤率（EBITDA 率單一來源；損益與資金共用）
A32: 起始 EBITDA 率（FY26） | B32: % | C32: 0.59
A33: 穩態 EBITDA 率（FY30） | B33: % | C33: 0.65
A34: EBITDA 率 | B34: % | C34: =輸入與假設!$C$32+(輸入與假設!$C$33-輸入與假設!$C$32)*0/4 -> 0.59 | D34: =輸入與假設!$C$32+(輸入與假設!$C$33-輸入與假設!$C$32)*1/4 -> 0.605 | E34: =輸入與假設!$C$32+(輸入與假設!$C$33-輸入與假設!$C$32)*2/4 -> 0.62 | F34: =輸入與假設!$C$32+(輸入與假設!$C$33-輸入與假設!$C$32)*3/4 -> 0.635 | G34: =輸入與假設!$C$32+(輸入與假設!$C$33-輸入與假設!$C$32)*4/4 -> 0.65
A35: 非算力服務現金 | B35: US$bn | C35: =輸入與假設!C$30*產能與收入!C24 -> 0.22478319 | D35: =輸入與假設!D$30*產能與收入!D24 -> 0.75576069 | E35: =輸入與假設!E$30*產能與收入!E24 -> 1.3479546 | F35: =輸入與假設!F$30*產能與收入!F24 -> 2.1166 | G35: =輸入與假設!G$30*產能與收入!G24 -> 2.9083713
A36: 電力／維護 overlay（1=開） | C36: 0
A37: 電價 | B37: $/MWh | C37: 60 | D37: 62 | E37: 64 | F37: 66 | G37: 68
A38: PUE | C38: 1.25 | D38: 1.24 | E38: 1.22 | F38: 1.2 | G38: 1.2
A39: 維護成本 | B39: US$m/MW | C39: 0.15 | D39: 0.15 | E39: 0.16 | F39: 0.16 | G39: 0.17
A40: D｜支出（CapEx、車隊折舊、租賃、JV）
A41: 提前支出比例 λ | B41: % | C41: 0.35
...

Sheet 收支與融資
A1: 支出與資金 — 五層支出、四層來源、現金橋
A2: FY26 欄＝1H 實際（10-Q 現金流量表口徑）＋下半年模型；FY27 以後為純模型。瀑布以「融資前現金」決定需求並直接由各支出列加總，因此沒有循環參照
A4: 項目 | B4: 單位 | C4: FY26 | D4: FY27 | E4: FY28 | F4: FY29 | G4: FY30
A5: 支出（五層）
A6: 客戶預付率 | B6: % | C6: =輸入與假設!C$50 -> 0.08 | D6: =輸入與假設!D$50 -> 0.08 | E6: =輸入與假設!E$50 -> 0.08 | F6: =輸入與假設!F$50 -> 0.08 | G6: =輸入與假設!G$50 -> 0.08
A7: 客戶預付金額（抵減，2H 起） | B7: US$bn | C7: =輸入與假設!C$63*C6 -> 1.66688 | D7: =輸入與假設!D$63*D6 -> 3.0668 | E7: =輸入與假設!E$63*E6 -> 2.3528 | F7: =輸入與假設!F$63*F6 -> 2.448 | G7: =輸入與假設!G$63*G6 -> 2.5976
A8: ① CapEx（用途用：1H 現金／2H 毛額） | B8: US$bn | C8: =輸入與假設!$C$121+輸入與假設!C$63 -> 34.953 | D8: =輸入與假設!D$63 -> 38.335 | E8: =輸入與假設!E$63 -> 29.41 | F8: =輸入與假設!F$63 -> 30.6 | G8: =輸入與假設!G$63 -> 32.47
A9: ② 在帳現金租金（備忘，1H 已含在 CFO） | B9: US$bn | C9: =輸入與假設!C$51 -> 1.04 | D9: =輸入與假設!D$51 -> 2.339 | E9: =輸入與假設!E$51 -> 2.306 | F9: =輸入與假設!F$51 -> 2.373 | G9: =輸入與假設!G$51 -> 2.289
A10: ② 表外現金租金（未起租） | B10: US$bn | C10: =輸入與假設!C$52 -> 0.3 | D10: =輸入與假設!D$52 -> 1.6 | E10: =輸入與假設!E$52 -> 2.4193548 | F10: =輸入與假設!F$52 -> 2.75 | G10: =輸入與假設!G$52 -> 2.9015385
A11: 租金合計 | B11: US$bn | C11: =C9+C10 -> 1.34 | D11: =D9+D10 -> 3.939 | E11: =E9+E10 -> 4.7253548 | F11: =F9+F10 -> 5.123 | G11: =G9+G10 -> 5.1905385
A12: ③ 存量債務利息（備忘，1H 已含在 CFO） | B12: US$bn | C12: =輸入與假設!C$86 -> 1.8058963 | D12: =輸入與假設!D$86 -> 2.4660068 | E12: =輸入與假設!E$86 -> 2.0200947 | F12: =輸入與假設!F$86 -> 1.7324815 | G12: =輸入與假設!G$86 -> 1.4951385 | I12: ="6/30 債務餘額的利息。FY26 全年利息＝1H 實際 1.176＋2H "&TEXT(C12,"0.0")&"＝"&TEXT(1.176+C12,"0.00")&"（見下方備忘）" -> 6/30 債務餘額的利息。FY26 全年利息＝1H 實際 1.176＋2H 1.8＝2.98（見下方備忘）
A13: 期初累積現金 | B13: US$bn | C13: =輸入與假設!$C$119 -> 3.127 | D13: =C40 -> 2 | E13: =D40 -> 2 | F13: =E40 -> 2 | G13: =F40 -> 2
A14: 新債利率 | B14: % | C14: =IF(輸入與假設!$C$81=1,輸入與假設!C$85+MAX(0,輸入與假設!$C$80-450)/100*0.004,輸入與假設!C$85) -> 0.09 | D14: =IF(輸入與假設!$C$81=1,輸入與假設!D$85+MAX(0,輸入與假設!$C$80-450)/100*0.004,輸入與假設!D$85) -> 0.09 | E14: =IF(輸入與假設!$C$81=1,輸入與假設!E$85+MAX(0,輸入與假設!$C$80-450)/100*0.004,輸入與假設!E$85) -> 0.09 | F14: =IF(輸入與假設!$C$81=1,輸入與假設!F$85+MAX(0,輸入與假設!$C$80-450)/100*0.004,輸入與假設!F$85) -> 0.09 | G14: =IF(輸入與假設!$C$81=1,輸入與假設!G$85+MAX(0,輸入與假設!$C$80-450)/100*0.004,輸入與假設!G$85) -> 0.09
A15: ③ 新債利息（瀑布） | B15: US$bn | C15: =C61 -> 0.56495231 | D15: =D61 -> 4.0708204 | E15: =E61 -> 5.5864719 | F15: =F61 -> 5.8690106 | G15: =G61 -> 6.515096
A16: 利息合計 | B16: US$bn | C16: =C12+C15 -> 2.3708486 | D16: =D12+D15 -> 6.5368271 | E16: =E12+E15 -> 7.6065666 | F16: =F12+F15 -> 7.6014921 | G16: =G12+G15 -> 8.0102346
A17: ④ JV／策略投資出資 | B17: US$bn | C17: =輸入與假設!$C$123+輸入與假設!C$55 -> 1.938 | D17: =輸入與假設!D$55 -> 0.4 | E17: =輸入與假設!E$55 -> 0.3 | F17: =輸入與假設!F$55 -> 0.2 | G17: =輸入與假設!G$55 -> 0.2
A18: 電力（overlay） | B18: US$bn | C18: =IF(輸入與假設!$C$36=1,產能與收入!C7*8760*輸入與假設!C$38*輸入與假設!C$37/1000000000*產能與收入!C5,0) -> 0 | D18: =IF(輸入與假設!$C$36=1,產能與收入!D7*8760*輸入與假設!D$38*輸入與假設!D$37/1000000000*產能與收入!D5,0) -> 0 | E18: =IF(輸入與假設!$C$36=1,產能與收入!E7*8760*輸入與假設!E$38*輸入與假設!E$37/1000000000*產能與收入!E5,0) -> 0 | F18: =IF(輸入與假設!$C$36=1,產能與收入!F7*8760*輸入與假設!F$38*輸入與假設!F$37/1000000000*產能與收入!F5,0) -> 0 | G18: =IF(輸入與假設!$C$36=1,產能與收入!G7*8760*輸入與假設!G$38*輸入與假設!G$37/1000000000*產能與收入!G5,0) -> 0
A19: 維護（overlay） | B19: US$bn | C19: =IF(輸入與假設!$C$36=1,產能與收入!C7*輸入與假設!C$39/1000*產能與收入!C5,0) -> 0 | D19: =IF(輸入與假設!$C$36=1,產能與收入!D7*輸入與假設!D$39/1000*產能與收入!D5,0) -> 0 | E19: =IF(輸入與假設!$C$36=1,產能與收入!E7*輸入與假設!E$39/1000*產能與收入!E5,0) -> 0 | F19: =IF(輸入與假設!$C$36=1,產能與收入!F7*輸入與假設!F$39/1000*產能與收入!F5,0) -> 0 | G19: =IF(輸入與假設!$C$36=1,產能與收入!G7*輸入與假設!G$39/1000*產能與收入!G5,0) -> 0
A20: ⑤ 排程還本（10-Q 本金表） | B20: US$bn | C20: =輸入與假設!$C$125+IF(輸入與假設!$C$71=1,輸入與假設!C$84,0) -> 9.632 | D20: =IF(輸入與假設!$C$71=1,輸入與假設!D$84,0) -> 6.184 | E20: =IF(輸入與假設!$C$71=1,輸入與假設!E$84,0) -> 4.416 | F20: =IF(輸入與假設!$C$71=1,輸入與假設!F$84,0) -> 2.421 | G20: =IF(輸入與假設!$C$71=1,輸入與假設!G$84,0) -> 3.221
A21: ⑥ capped call 支出（1H 實際） | B21: US$bn | C21: =輸入與假設!$C$126 -> 0.492 | D21: =0 -> 0 | E21: =0 -> 0 | F21: =0 -> 0 | G21: =0 -> 0
A22: 用途合計（現金口徑） | B22: US$bn | C22: =C8+C11+C16+C17+C18+C19+C20+C21 -> 50.725849 | D22: =D8+D11+D16+D17+D18+D19+D20+D21 -> 55.394827 | E22: =E8+E11+E16+E17+E18+E19+E20+E21 -> 46.457921 | F22: =F8+F11+F16+F17+F18+F19+F20+F21 -> 45.945492 | G22: =G8+G11+G16+G17+G18+G19+G20+G21 -> 49.091773
A23: 來源（四層）
A24: Ⓐ0 1H26 實際營運現金流（CFO） | B24: US$bn | C24: =輸入與假設!$C$120 -> 3.663 | D24: =0 -> 0 | E24: =0 -> 0 | F24: =0 -> 0 | G24: =0 -> 0
A25: Ⓐ RPO 現金（2H 起） | B25: US$bn | C25: =產能與收入!C25 -> 6.0636896 | D25: =產能與收入!D25 -> 18.895425 | E25: =產能與收入!E25 -> 19.131182 | F25: =產能與收入!F25 -> 18.78145 | G25: =產能與收入!G25 -> 13.374717
A26: Ⓑ 新簽約現金 | B26: US$bn | C26: =產能與收入!C26 -> 0 | D26: =產能與收入!D26 -> 0 | E26: =產能與收入!E26 -> 6.7854123 | F26: =產能與收入!F26 -> 10.826919 | G26: =產能與收入!G26 -> 17.759402
A27: Ⓒ 非算力服務現金 | B27: US$bn | C27: =輸入與假設!C$35 -> 0.22478319 | D27: =輸入與假設!D$35 -> 0.75576069 | E27: =輸入與假設!E$35 -> 1.3479546 | F27: =輸入與假設!F$35 -> 2.1166 | G27: =輸入與假設!G$35 -> 2.9083713
A28: Ⓓ 客戶預付（2H 起） | B28: US$bn | C28: =C7 -> 1.66688 | D28: =D7 -> 3.0668 | E28: =E7 -> 2.3528 | F28: =F7 -> 2.448 | G28: =G7 -> 2.5976
A29: 營運來源合計 | B29: US$bn | C29: =C24+C25+C26+C27+C28 -> 11.618353 | D29: =D24+D25+D26+D27+D28 -> 22.717986 | E29: =E24+E25+E26+E27+E28 -> 29.617349 | F29: =F24+F25+F26+F27+F28 -> 34.172969 | G29: =G24+G25+G26+G27+G28 -> 36.64009
A30: Ⓔ 股權／可轉債（融資） | B30: US$bn | C30: =輸入與假設!$C$127+IF(輸入與假設!$C$68=1,輸入與假設!$C$67,0) -> 9.182 | D30: =0 -> 0 | E30: =0 -> 0 | F30: =0 -> 0 | G30: =0 -> 0
A31: Ⓕ 1H26 實際借款（融資） | B31: US$bn | C31: =輸入與假設!$C$124 -> 16.747 | D31: =0 -> 0 | E31: =0 -> 0 | F31: =0 -> 0 | G31: =0 -> 0
A32: Ⓖ 瀑布：新債（額度＋資產層） | B32: US$bn | C32: =C56 -> 12.554496 | D32: =D56 -> 32.676842 | E32: =E56 -> 16.840572 | F32: =F56 -> 3.1393189 | G32: =G56 -> 7.1787275
A33: Ⓗ 瀑布：股權募資 | B33: US$bn | C33: =C59 -> 0 | D33: =D59 -> 0 | E33: =E59 -> 0 | F33: =F59 -> 8.6332038 | G33: =G59 -> 5.2729553
A34: Ⓘ 瀑布：高息債（股權上限溢出） | B34: US$bn | C34: =C60 -> 0 | D34: =D60 -> 0 | E34: =E60 -> 0 | F34: =F60 -> 0 | G34: =G60 -> 0
A35: 總來源（含融資） | B35: US$bn | C35: =C29+C30+C31+C32+C33+C34 -> 50.101849 | D35: =D29+D30+D31+D32+D33+D34 -> 55.394827 | E35: =E29+E30+E31+E32+E33+E34 -> 46.457921 | F35: =F29+F30+F31+F32+F33+F34 -> 45.945492 | G35: =G29+G30+G31+G32+G33+G34 -> 49.091773
A36: 缺口與現金橋
A37: 1H 其他／受限現金調節 | B37: US$bn | C37: =輸入與假設!$C$66-(輸入與假設!$C$119+輸入與假設!$C$120+輸入與假設!$C$124+輸入與假設!$C$127-輸入與假設!$C$121-輸入與假設!$C$123-輸入與假設!$C$125-輸入與假設!$C$126) -> -0.503 | D37: =0 -> 0 | E37: =0 -> 0 | F37: =0 -> 0 | G37: =0 -> 0
A38: 營運缺口（不含融資、不含還本） | B38: US$bn | C38: =C29-(C22-C20-C21) -> -28.983496 | D38: =D29-(D22-D20-D21) -> -26.492842 | E38: =E29-(E22-E20-E21) -> -12.424572 | F38: =F29-(F22-F20-F21) -> -9.3515227 | G38: =G29-(G22-G20-G21) -> -9.2306828
A39: 期間缺口（含融資） | B39: US$bn | C39: =C35-C22+C37 -> -1.127 | D39: =D35-D22+D37 -> 0 | E39: =E35-E22+E37 -> 0 | F39: =F35-F22+F37 -> 0 | G39: =G35-G22+G37 -> 0
A40: 期末累積現金 | B40: US$bn | C40: =C13+C39 -> 2 | D40: =D13+D39 -> 2 | E40: =E13+E39 -> 2 | F40: =F13+F39 -> 2 | G40: =G13+G39 -> 2
A41: 期前融資瀑布（缺口在需要前一期先融好：額度 → 資產層新債 → 股權）
...

Sheet 季度追蹤
A1: 季度追蹤 — 焦點季的模型／共識／指引／實際與差距（由年度模型拆分；只用於追蹤，不影響年度數字與目標價）
A2: 設定與實際數在『輸入與假設』J 區，共識在 I 區；缺資料顯示「不適用」，實際數空白＝待公布。差距超過門檻的項目附差異原因（拆法＝所屬期間合計差距在門檻內）。第 2 區為 6 季路徑與拆分明細（預設收合）。
A4: 1｜焦點季（『輸入與假設』J 區選擇）：模型／共識／指引／實際與差距
A5: 焦點｜營收 | B5: US$bn | C5: =INDEX($C$20:$H$20,輸入與假設!$C$154) -> 3.6626667 | D5: =INDEX($C$39:$H$39,輸入與假設!$C$154) -> 3.541 | E5: =INDEX($C$49:$H$49,輸入與假設!$C$154) -> 0.034359409 | F5: =IF(ISNUMBER(INDEX($C$29:$H$29,輸入與假設!$C$154)),INDEX($C$29:$H$29,輸入與假設!$C$154),"不適用") -> 3.45 | G5: =INDEX($C$30:$H$30,輸入與假設!$C$154) -> 3.6 | H5: =INDEX($C$50:$H$50,輸入與假設!$C$154) -> 0.039054374 | I5: =IF(ISNUMBER(INDEX($C$43:$H$43,輸入與假設!$C$154)),INDEX($C$43:$H$43,輸入與假設!$C$154),"待公布") -> 待公布 | J5: =INDEX($C$51:$H$51,輸入與假設!$C$154) | K5: =INDEX($C$52:$H$52,輸入與假設!$C$154) | L5: =INDEX($C$53:$H$53,輸入與假設!$C$154)
A6: 焦點｜調整後 EBITDA | B6: US$bn | C6: =INDEX($C$26:$H$26,輸入與假設!$C$154) -> 2.1509613 | D6: =INDEX($C$40:$H$40,輸入與假設!$C$154) -> 2.047 | E6: =INDEX($C$54:$H$54,輸入與假設!$C$154) -> 0.10396126 | F6: 不適用 | G6: 不適用 | H6: =INDEX($C$55:$H$55,輸入與假設!$C$154) -> 不適用 | I6: =IF(ISNUMBER(INDEX($C$44:$H$44,輸入與假設!$C$154)),INDEX($C$44:$H$44,輸入與假設!$C$154),"待公布") -> 待公布 | J6: =INDEX($C$56:$H$56,輸入與假設!$C$154) | K6: =INDEX($C$57:$H$57,輸入與假設!$C$154) | L6: =INDEX($C$58:$H$58,輸入與假設!$C$154) | M6: =INDEX($C$59:$H$59,輸入與假設!$C$154) -> 0.009181165 | N6: =INDEX($C$60:$H$60,輸入與假設!$C$154) -> 不適用 | O6: =INDEX($C$61:$H$61,輸入與假設!$C$154) | P6: =INDEX($C$62:$H$62,輸入與假設!$C$154) | Q6: =INDEX($C$63:$H$63,輸入與假設!$C$154)
A7: 焦點｜EBITDA 率 | B7: % | C7: =INDEX($C$25:$H$25,輸入與假設!$C$154) -> 0.58726645 | D7: =INDEX($C$41:$H$41,輸入與假設!$C$154) -> 0.57808529 | E7: =INDEX($C$64:$H$64,輸入與假設!$C$154) -> 0.009181165 | F7: 不適用 | G7: 不適用 | H7: =INDEX($C$65:$H$65,輸入與假設!$C$154) -> 不適用 | I7: =IF(ISNUMBER(INDEX($C$45:$H$45,輸入與假設!$C$154)),INDEX($C$45:$H$45,輸入與假設!$C$154),"待公布") -> 待公布 | J7: =INDEX($C$66:$H$66,輸入與假設!$C$154) | K7: =INDEX($C$67:$H$67,輸入與假設!$C$154) | L7: =INDEX($C$68:$H$68,輸入與假設!$C$154)
A8: 焦點｜調整後營業利益 | B8: US$bn | C8: =INDEX($C$28:$H$28,輸入與假設!$C$154) -> -0.013413743 | D8: 不適用 | E8: =INDEX($C$69:$H$69,輸入與假設!$C$154) -> 不適用 | F8: =IF(ISNUMBER(INDEX($C$31:$H$31,輸入與假設!$C$154)),INDEX($C$31:$H$31,輸入與假設!$C$154),IF(INDEX($C$33:$H$33,輸入與假設!$C$154)<>"",INDEX($C$33:$H$33,輸入與假設!$C$154),"不適用")) -> 0.2 | G8: =INDEX($C$32:$H$32,輸入與假設!$C$154) -> 0.26 | H8: =INDEX($C$70:$H$70,輸入與假設!$C$154) -> -0.24341374 | I8: =IF(ISNUMBER(INDEX($C$46:$H$46,輸入與假設!$C$154)),INDEX($C$46:$H$46,輸入與假設!$C$154),"待公布") -> 待公布 | J8: =INDEX($C$71:$H$71,輸入與假設!$C$154) | K8: =INDEX($C$72:$H$72,輸入與假設!$C$154) | L8: =INDEX($C$73:$H$73,輸入與假設!$C$154) | M8: =INDEX($C$74:$H$74,輸入與假設!$C$154) -> 不適用 | N8: =INDEX($C$75:$H$75,輸入與假設!$C$154) -> -0.068910516 | O8: =INDEX($C$76:$H$76,輸入與假設!$C$154) | P8: =INDEX($C$77:$H$77,輸入與假設!$C$154) | Q8: =INDEX($C$78:$H$78,輸入與假設!$C$154)
A9: 焦點｜CapEx（毛額） | B9: US$bn | C9: =INDEX($C$38:$H$38,輸入與假設!$C$154) -> 12.5 | D9: 不適用 | E9: =INDEX($C$79:$H$79,輸入與假設!$C$154) -> 不適用 | F9: =IF(ISNUMBER(INDEX($C$34:$H$34,輸入與假設!$C$154)),INDEX($C$34:$H$34,輸入與假設!$C$154),"不適用") -> 11.5 | G9: =INDEX($C$35:$H$35,輸入與假設!$C$154) -> 13.5 | H9: =INDEX($C$80:$H$80,輸入與假設!$C$154) -> 0 | I9: =IF(ISNUMBER(INDEX($C$47:$H$47,輸入與假設!$C$154)),INDEX($C$47:$H$47,輸入與假設!$C$154),"待公布") -> 待公布 | J9: =INDEX($C$81:$H$81,輸入與假設!$C$154) | K9: =INDEX($C$82:$H$82,輸入與假設!$C$154) | L9: =INDEX($C$83:$H$83,輸入與假設!$C$154)
A10: 焦點｜季末 Accepted MW | B10: MW | C10: =INDEX($C$17:$H$17,輸入與假設!$C$154) -> 1675 | D10: 不適用 | E10: =INDEX($C$84:$H$84,輸入與假設!$C$154) -> 不適用 | F10: 不適用 | G10: 不適用 | H10: =INDEX($C$85:$H$85,輸入與假設!$C$154) -> 不適用 | I10: =IF(ISNUMBER(INDEX($C$48:$H$48,輸入與假設!$C$154)),INDEX($C$48:$H$48,輸入與假設!$C$154),"待公布") -> 待公布 | J10: =INDEX($C$86:$H$86,輸入與假設!$C$154) | K10: =INDEX($C$87:$H$87,輸入與假設!$C$154) | L10: =INDEX($C$88:$H$88,輸入與假設!$C$154)
A11: 焦點｜季度 | C11: =INDEX($C$14:$H$14,輸入與假設!$C$154) -> Q3'26
A12: 焦點｜差異原因 | C12: =IF(INDEX($C$131:$H$131,輸入與假設!$C$154)="","無（差距皆在 "&IF(ROUND(ABS(輸入與假設!$C$150)*100,4)=INT(ROUND(ABS(輸入與假設!$C$150)*100,4)),TEXT(ROUND(ABS(輸入與假設!$C$150)*100,4),"0"),TEXT(ROUND(ABS(輸入與假設!$C$150)*100,4),"0.0"))&"%"&" 以內）",INDEX($C$131:$H$131,輸入與假設!$C$154)) -> 營收 vs 指引中點 +3.9%：觀點（水準 +$0.115bn（2H26 模型 $8.413bn，指引隱含 $8.147bn）；分配 +$0.023bn）；調整後營業利益 vs 指引中點 −$0.24bn／−6.9pt：已知限制（對照指引隱含折舊 1.82（＝共識 EBITDA 2.05 − 指引中點 0.23，Derived），模型折舊 2.16；缺口 −0.24 ≈ 折舊 −0.35 ＋ EBITDA +0.10；待辦 6 修正折舊）
A13: 2｜6 季路徑、共識、指引、實際與差距（明細；第 1 區以焦點季引用本區）
A14: 項目 | B14: 單位 | C14: Q3'26 | D14: Q4'26 | E14: Q1'27 | F14: Q2'27 | G14: Q3'27 | H14: Q4'27
A15: 所屬期間 | C15: =輸入與假設!C$153 -> 1 | D15: =輸入與假設!D$153 -> 1 | E15: =輸入與假設!E$153 -> 2 | F15: =輸入與假設!F$153 -> 2 | G15: =輸入與假設!G$153 -> 2 | H15: =輸入與假設!H$153 -> 2
A16: 季序 | C16: 1 | D16: 2 | E16: 3 | F16: 4 | G16: 5 | H16: 6
A17: 季末 Accepted MW（模型） | B17: MW | C17: =輸入與假設!$C$156+(輸入與假設!C$23-輸入與假設!$C$156)*1/2 -> 1675 | D17: =輸入與假設!$C$156+(輸入與假設!C$23-輸入與假設!$C$156)*2/2 -> 1850 | E17: =輸入與假設!C$23+(輸入與假設!D$23-輸入與假設!C$23)*1/4 -> 2162.5 | F17: =輸入與假設!C$23+(輸入與假設!D$23-輸入與假設!C$23)*2/4 -> 2475 | G17: =輸入與假設!C$23+(輸入與假設!D$23-輸入與假設!C$23)*3/4 -> 2787.5 | H17: =輸入與假設!C$23+(輸入與假設!D$23-輸入與假設!C$23)*4/4 -> 3100
A18: 平均在役 MW（Billable，拆分依據） | B18: MW | C18: =輸入與假設!$C$18+(輸入與假設!C$24-輸入與假設!$C$18)*1/4 -> 1437.5 | D18: =輸入與假設!$C$18+(輸入與假設!C$24-輸入與假設!$C$18)*3/4 -> 1612.5 | E18: =輸入與假設!C$24+(輸入與假設!D$24-輸入與假設!C$24)*1/8 -> 1850 | F18: =輸入與假設!C$24+(輸入與假設!D$24-輸入與假設!C$24)*3/8 -> 2150 | G18: =輸入與假設!C$24+(輸入與假設!D$24-輸入與假設!C$24)*5/8 -> 2450 | H18: =輸入與假設!C$24+(輸入與假設!D$24-輸入與假設!C$24)*7/8 -> 2750
A19: 季內新增 Accepted MW | B19: MW | C19: =C17-輸入與假設!$C$156 -> 175 | D19: =D17-C17 -> 175 | E19: =E17-輸入與假設!C$23 -> 312.5 | F19: =F17-E17 -> 312.5 | G19: =G17-F17 -> 312.5 | H19: =H17-G17 -> 312.5
A20: 營收（模型） | B20: US$bn | C20: =輸入與假設!$C$155+1*(損益與評價!C8-2*輸入與假設!$C$155)/3 -> 3.6626667 | D20: =輸入與假設!$C$155+2*(損益與評價!C8-2*輸入與假設!$C$155)/3 -> 4.7503333 | E20: =損益與評價!D8*E18/(E18+F18+G18+H18) -> 5.2538995 | F20: =損益與評價!D8*F18/(E18+F18+G18+H18) -> 6.1058832 | G20: =損益與評價!D8*G18/(E18+F18+G18+H18) -> 6.9578668 | H20: =損益與評價!D8*H18/(E18+F18+G18+H18) -> 7.8098505
A21: EBITDA 率直線｜各期營收合計 S | C21: =C20+D20 -> 8.413 | D21: =E20+F20+G20+H20 -> 26.1275
A22: EBITDA 率直線｜營收 × 季序合計 T | C22: =C20*C16+D20*D16 -> 13.163333 | D22: =E20*E16+F20*F16+G20*G16+H20*H16 -> 121.83367
A23: EBITDA 率直線｜年度 EBITDA E | C23: =損益與評價!C11 -> 4.96367 | D23: =損益與評價!D11 -> 15.807137
A24: EBITDA 率直線｜截距 a／斜率 b | C24: =(C23*D22-C22*D23)/(C21*D22-C22*D21) -> 0.58242525 | D24: =(C21*D23-D21*C23)/(C21*D22-C22*D21) -> 0.0048412061
A25: EBITDA 率（模型） | B25: % | C25: =$C$24+$D$24*C16 -> 0.58726645 | D25: =$C$24+$D$24*D16 -> 0.59210766 | E25: =$C$24+$D$24*E16 -> 0.59694886 | F25: =$C$24+$D$24*F16 -> 0.60179007 | G25: =$C$24+$D$24*G16 -> 0.60663128 | H25: =$C$24+$D$24*H16 -> 0.61147248
A26: 調整後 EBITDA（模型） | B26: US$bn | C26: =C20*C25 -> 2.1509613 | D26: =D20*D25 -> 2.8127087 | E26: =E20*E25 -> 3.1363093 | F26: =F20*F25 -> 3.6744598 | G26: =G20*G25 -> 4.2208596 | H26: =H20*H25 -> 4.7755087
A27: 車隊折舊（模型） | B27: US$bn | C27: =(輸入與假設!C$62+輸入與假設!C$60*1/4)/輸入與假設!$C$44*輸入與假設!C$21/2 -> 2.164375 | D27: =(輸入與假設!C$62+輸入與假設!C$60*3/4)/輸入與假設!$C$44*輸入與假設!C$21/2 -> 2.5984583 | E27: =(輸入與假設!D$62+輸入與假設!D$60*1/8)/輸入與假設!$C$44*輸入與假設!D$21/4 -> 3.0151615 | F27: =(輸入與假設!D$62+輸入與假設!D$60*3/8)/輸入與假設!$C$44*輸入與假設!D$21/4 -> 3.4144844 | G27: =(輸入與假設!D$62+輸入與假設!D$60*5/8)/輸入與假設!$C$44*輸入與假設!D$21/4 -> 3.8138073 | H27: =(輸入與假設!D$62+輸入與假設!D$60*7/8)/輸入與假設!$C$44*輸入與假設!D$21/4 -> 4.2131302
A28: 調整後營業利益（模型） | B28: US$bn | C28: =C26-C27 -> -0.013413743 | D28: =D26-D27 -> 0.21425041 | E28: =E26-E27 -> 0.12114785 | F28: =F26-F27 -> 0.25997547 | G28: =G26-G27 -> 0.40705235 | H28: =H26-H27 -> 0.56237849
A29: 指引｜營收（低） | B29: US$bn | C29: =IF(ISNUMBER(輸入與假設!C$162),輸入與假設!C$162,"不適用") -> 3.45 | D29: =IF(ISNUMBER(輸入與假設!D$162),輸入與假設!D$162,"不適用") -> 不適用 | E29: =IF(ISNUMBER(輸入與假設!E$162),輸入與假設!E$162,"不適用") -> 不適用 | F29: =IF(ISNUMBER(輸入與假設!F$162),輸入與假設!F$162,"不適用") -> 不適用 | G29: =IF(ISNUMBER(輸入與假設!G$162),輸入與假設!G$162,"不適用") -> 不適用 | H29: =IF(ISNUMBER(輸入與假設!H$162),輸入與假設!H$162,"不適用") -> 不適用
A30: 指引｜營收（高） | B30: US$bn | C30: =IF(ISNUMBER(輸入與假設!C$163),輸入與假設!C$163,"不適用") -> 3.6 | D30: =IF(ISNUMBER(輸入與假設!D$163),輸入與假設!D$163,"不適用") -> 不適用 | E30: =IF(ISNUMBER(輸入與假設!E$163),輸入與假設!E$163,"不適用") -> 不適用 | F30: =IF(ISNUMBER(輸入與假設!F$163),輸入與假設!F$163,"不適用") -> 不適用 | G30: =IF(ISNUMBER(輸入與假設!G$163),輸入與假設!G$163,"不適用") -> 不適用 | H30: =IF(ISNUMBER(輸入與假設!H$163),輸入與假設!H$163,"不適用") -> 不適用
A31: 指引｜調整後營業利益（低） | B31: US$bn | C31: =IF(ISNUMBER(輸入與假設!C$164),輸入與假設!C$164,"不適用") -> 0.2 | D31: =IF(ISNUMBER(輸入與假設!D$164),輸入與假設!D$164,"不適用") -> 不適用 | E31: =IF(ISNUMBER(輸入與假設!E$164),輸入與假設!E$164,"不適用") -> 不適用 | F31: =IF(ISNUMBER(輸入與假設!F$164),輸入與假設!F$164,"不適用") -> 不適用 | G31: =IF(ISNUMBER(輸入與假設!G$164),輸入與假設!G$164,"不適用") -> 不適用 | H31: =IF(ISNUMBER(輸入與假設!H$164),輸入與假設!H$164,"不適用") -> 不適用
A32: 指引｜調整後營業利益（高） | B32: US$bn | C32: =IF(ISNUMBER(輸入與假設!C$165),輸入與假設!C$165,"不適用") -> 0.26 | D32: =IF(ISNUMBER(輸入與假設!D$165),輸入與假設!D$165,"不適用") -> 不適用 | E32: =IF(ISNUMBER(輸入與假設!E$165),輸入與假設!E$165,"不適用") -> 不適用 | F32: =IF(ISNUMBER(輸入與假設!F$165),輸入與假設!F$165,"不適用") -> 不適用 | G32: =IF(ISNUMBER(輸入與假設!G$165),輸入與假設!G$165,"不適用") -> 不適用 | H32: =IF(ISNUMBER(輸入與假設!H$165),輸入與假設!H$165,"不適用") -> 不適用
A33: 指引（文字）｜調整後營業利益 | C33: =IF(ISTEXT(輸入與假設!C$168),輸入與假設!C$168,"") | D33: =IF(ISTEXT(輸入與假設!D$168),輸入與假設!D$168,"") -> 調整後營業利益率 low teens | E33: =IF(ISTEXT(輸入與假設!E$168),輸入與假設!E$168,"") | F33: =IF(ISTEXT(輸入與假設!F$168),輸入與假設!F$168,"") | G33: =IF(ISTEXT(輸入與假設!G$168),輸入與假設!G$168,"") | H33: =IF(ISTEXT(輸入與假設!H$168),輸入與假設!H$168,"")
A34: 指引｜CapEx（毛額）（低） | B34: US$bn | C34: =IF(ISNUMBER(輸入與假設!C$166),輸入與假設!C$166,"不適用") -> 11.5 | D34: =IF(ISNUMBER(輸入與假設!D$166),輸入與假設!D$166,"不適用") -> 不適用 | E34: =IF(ISNUMBER(輸入與假設!E$166),輸入與假設!E$166,"不適用") -> 不適用 | F34: =IF(ISNUMBER(輸入與假設!F$166),輸入與假設!F$166,"不適用") -> 不適用 | G34: =IF(ISNUMBER(輸入與假設!G$166),輸入與假設!G$166,"不適用") -> 不適用 | H34: =IF(ISNUMBER(輸入與假設!H$166),輸入與假設!H$166,"不適用") -> 不適用
A35: 指引｜CapEx（毛額）（高） | B35: US$bn | C35: =IF(ISNUMBER(輸入與假設!C$167),輸入與假設!C$167,"不適用") -> 13.5 | D35: =IF(ISNUMBER(輸入與假設!D$167),輸入與假設!D$167,"不適用") -> 不適用 | E35: =IF(ISNUMBER(輸入與假設!E$167),輸入與假設!E$167,"不適用") -> 不適用 | F35: =IF(ISNUMBER(輸入與假設!F$167),輸入與假設!F$167,"不適用") -> 不適用 | G35: =IF(ISNUMBER(輸入與假設!G$167),輸入與假設!G$167,"不適用") -> 不適用 | H35: =IF(ISNUMBER(輸入與假設!H$167),輸入與假設!H$167,"不適用") -> 不適用
A36: CapEx 指引錨定值 | B36: US$bn | C36: =IF(AND(ISNUMBER(C34),ISNUMBER(C35)),((C34+C35)/2),"") -> 12.5 | D36: =IF(AND(ISNUMBER(D34),ISNUMBER(D35)),((D34+D35)/2),"") | E36: =IF(AND(ISNUMBER(E34),ISNUMBER(E35)),((E34+E35)/2),"") | F36: =IF(AND(ISNUMBER(F34),ISNUMBER(F35)),((F34+F35)/2),"") | G36: =IF(AND(ISNUMBER(G34),ISNUMBER(G35)),((G34+G35)/2),"") | H36: =IF(AND(ISNUMBER(H34),ISNUMBER(H35)),((H34+H35)/2),"")
A37: CapEx 未錨定季的新增 MW | B37: MW | C37: =IF(ISNUMBER(C36),0,C19) -> 0 | D37: =IF(ISNUMBER(D36),0,D19) -> 175 | E37: =IF(ISNUMBER(E36),0,E19) -> 312.5 | F37: =IF(ISNUMBER(F36),0,F19) -> 312.5 | G37: =IF(ISNUMBER(G36),0,G19) -> 312.5 | H37: =IF(ISNUMBER(H36),0,H19) -> 312.5
A38: CapEx（毛額）（模型） | B38: US$bn | C38: =IF(ISNUMBER(C36),C36,IF((C37+D37)>0,(輸入與假設!C$63-SUM(C36,D36))*C37/(C37+D37),(輸入與假設!C$63-SUM(C36,D36))/(2-COUNT(C36,D36)))) -> 12.5 | D38: =IF(ISNUMBER(D36),D36,IF((C37+D37)>0,(輸入與假設!C$63-SUM(C36,D36))*D37/(C37+D37),(輸入與假設!C$63-SUM(C36,D36))/(2-COUNT(C36,D36)))) -> 8.336 | E38: =IF(ISNUMBER(E36),E36,IF((E37+F37+G37+H37)>0,(輸入與假設!D$63-SUM(E36,F36,G36,H36))*E37/(E37+F37+G37+H37),(輸入與假設!D$63-SUM(E36,F36,G36,H36))/(4-COUNT(E36,F36,G36,H36)))) -> 9.58375 | F38: =IF(ISNUMBER(F36),F36,IF((E37+F37+G37+H37)>0,(輸入與假設!D$63-SUM(E36,F36,G36,H36))*F37/(E37+F37+G37+H37),(輸入與假設!D$63-SUM(E36,F36,G36,H36))/(4-COUNT(E36,F36,G36,H36)))) -> 9.58375 | G38: =IF(ISNUMBER(G36),G36,IF((E37+F37+G37+H37)>0,(輸入與假設!D$63-SUM(E36,F36,G36,H36))*G37/(E37+F37+G37+H37),(輸入與假設!D$63-SUM(E36,F36,G36,H36))/(4-COUNT(E36,F36,G36,H36)))) -> 9.58375 | H38: =IF(ISNUMBER(H36),H36,IF((E37+F37+G37+H37)>0,(輸入與假設!D$63-SUM(E36,F36,G36,H36))*H37/(E37+F37+G37+H37),(輸入與假設!D$63-SUM(E36,F36,G36,H36))/(4-COUNT(E36,F36,G36,H36)))) -> 9.58375
A39: 共識｜營收 | B39: US$bn | C39: =IF(ISNUMBER(輸入與假設!$C$147),輸入與假設!$C$147,"不適用") -> 3.541 | D39: =IF(ISNUMBER(輸入與假設!$D$147),輸入與假設!$D$147,"不適用") -> 4.706 | E39: 不適用 | F39: 不適用 | G39: 不適用 | H39: 不適用
A40: 共識｜調整後 EBITDA | B40: US$bn | C40: =IF(ISNUMBER(輸入與假設!$C$148),輸入與假設!$C$148,"不適用") -> 2.047 | D40: =IF(ISNUMBER(輸入與假設!$D$148),輸入與假設!$D$148,"不適用") -> 2.897 | E40: 不適用 | F40: 不適用 | G40: 不適用 | H40: 不適用
A41: 共識｜EBITDA 率 [Derived] | B41: % | C41: =IF(AND(ISNUMBER(輸入與假設!$C$148),ISNUMBER(輸入與假設!$C$147)),輸入與假設!$C$148/輸入與假設!$C$147,"不適用") -> 0.57808529 | D41: =IF(AND(ISNUMBER(輸入與假設!$D$148),ISNUMBER(輸入與假設!$D$147)),輸入與假設!$D$148/輸入與假設!$D$147,"不適用") -> 0.61559711 | E41: 不適用 | F41: 不適用 | G41: 不適用 | H41: 不適用
...

Sheet 產能與收入
A1: 產能與收入 — 合約排程 vs 機房產能
A2: 兩條線獨立產生後相減：排程>容量→瓶頸（收不到）；容量>排程→剩餘產能（要靠新簽約賣掉）
A3: FY26 欄口徑：MW 為年底存量；標示「（模型期）」的收入列只含 2026 下半年——RPO 桶自 2026-06-30 起算，1H 收入已實現、不再受產能約束。1H 實際單列，兩者相加即 FY26 全年（見本頁「FY26 全年」列）。
A5: 模型期長度（年） | C5: =輸入與假設!C$21 -> 0.5 | D5: =輸入與假設!D$21 -> 1 | E5: =輸入與假設!E$21 -> 1 | F5: =輸入與假設!F$21 -> 1 | G5: =輸入與假設!G$21 -> 1
A6: （A）機房：容量上限
A7: Accepted MW（已驗收，單調不減） | B7: MW | C7: =MAX(0,輸入與假設!C$23) -> 1850 | D7: =MAX(輸入與假設!D$23,C7) -> 3100 | E7: =MAX(輸入與假設!E$23,D7) -> 4000 | F7: =MAX(輸入與假設!F$23,E7) -> 4800 | G7: =MAX(輸入與假設!G$23,F7) -> 5600
A8: Billable MW（上限為 Accepted） | B8: MW | C8: =MIN(MAX(0,輸入與假設!C$24),C7) -> 1700 | D8: =MIN(MAX(0,輸入與假設!D$24),D7) -> 2900 | E8: =MIN(MAX(0,輸入與假設!E$24),E7) -> 3739 | F8: =MIN(MAX(0,輸入與假設!F$24),F7) -> 4495 | G8: =MIN(MAX(0,輸入與假設!G$24),G7) -> 5250
A9: 期初在役 MW | B9: MW | C9: =輸入與假設!$C$18 -> 1350 | D9: =C8 -> 1700 | E9: =D8 -> 2900 | F9: =E8 -> 3739 | G9: =F8 -> 4495
A10: 平均在役 MW（FY26 欄為下半年平均） | B10: MW | C10: =IF(輸入與假設!$C$19=1,(C9+C8)/2,C8) -> 1525 | D10: =IF(輸入與假設!$C$19=1,(D9+D8)/2,D8) -> 2300 | E10: =IF(輸入與假設!$C$19=1,(E9+E8)/2,E8) -> 3319.5 | F10: =IF(輸入與假設!$C$19=1,(F9+F8)/2,F8) -> 4117 | G10: =IF(輸入與假設!$C$19=1,(G9+G8)/2,G8) -> 4872.5
A11: 容量上限（模型期最多能交付的收入） | B11: US$bn | C11: =C10*輸入與假設!C$26*輸入與假設!$C$20*輸入與假設!C$25*C5 -> 8.113 | D11: =D10*輸入與假設!D$26*輸入與假設!$C$20*輸入與假設!D$25*D5 -> 25.1275 | E11: =E10*輸入與假設!E$26*輸入與假設!$C$20*輸入與假設!E$25*E5 -> 35.883795 | F11: =F10*輸入與假設!F$26*輸入與假設!$C$20*輸入與假設!F$25*F5 -> 42.11691 | G11: =G10*輸入與假設!G$26*輸入與假設!$C$20*輸入與假設!G$25*G5 -> 47.06835
A12: （B）合約：排程 RPO
A13: 排程 RPO（模型期，依 10-Q 桶分攤） | B13: US$bn | C13: =(輸入與假設!$C$13+輸入與假設!$C$14)*(輸入與假設!C$22/輸入與假設!$C$16)*輸入與假設!$C$15 -> 13.19175 | D13: =(輸入與假設!$C$13+輸入與假設!$C$14)*(輸入與假設!D$22/輸入與假設!$C$16)*輸入與假設!$C$15 -> 26.3835 | E13: =(輸入與假設!$C$13+輸入與假設!$C$14)*(輸入與假設!E$22/輸入與假設!$C$16)*輸入與假設!$C$15 -> 25.74 | F13: =(輸入與假設!$C$13+輸入與假設!$C$14)*(輸入與假設!F$22/輸入與假設!$C$16)*輸入與假設!$C$15 -> 25.0965 | G13: =(輸入與假設!$C$13+輸入與假設!$C$14)*(輸入與假設!G$22/輸入與假設!$C$16)*輸入與假設!$C$15 -> 17.69625
A14: （C）兩條線相減
A15: 產能瓶頸（模型期：排程 − 容量） | B15: US$bn | C15: =MAX(0,C13-C11) -> 5.07875 | D15: =MAX(0,D13-D11) -> 1.256 | E15: =MAX(0,E13-E11) -> 0 | F15: =MAX(0,F13-F11) -> 0 | G15: =MAX(0,G13-G11) -> 0
A16: 期初 RPO 轉換收入（模型期） | B16: US$bn | C16: =C13-C15 -> 8.113 | D16: =D13-D15 -> 25.1275 | E16: =E13-E15 -> 25.74 | F16: =F13-F15 -> 25.0965 | G16: =G13-G15 -> 17.69625
A17: 未被期初 RPO 占用的產能 | B17: US$bn | C17: =MAX(0,C11-C13) -> 0 | D17: =MAX(0,D11-D13) -> 0 | E17: =MAX(0,E11-E13) -> 10.143795 | F17: =MAX(0,F11-F13) -> 17.02041 | G17: =MAX(0,G11-G13) -> 29.3721
A18: 新簽約收入 | B18: US$bn | C18: =C17*輸入與假設!C$27 -> 0 | D18: =D17*輸入與假設!D$27 -> 0 | E18: =E17*輸入與假設!E$27 -> 9.1294155 | F18: =F17*輸入與假設!F$27 -> 14.467348 | G18: =G17*輸入與假設!G$27 -> 23.49768
A19: 損益用算力收入（模型期＝RPO 轉換＋新簽約） | B19: US$bn | C19: =C16+C18 -> 8.113 | D19: =D16+D18 -> 25.1275 | E19: =E16+E18 -> 34.869416 | F19: =F16+F18 -> 39.563848 | G19: =G16+G18 -> 41.19393
A20: （D）收入 → 現金：三道折扣
A21: 信用損失（期初 RPO 部分） | B21: US$bn | C21: =C16*輸入與假設!C$28*(1-輸入與假設!C$29) -> 0.0202825 | D21: =D16*輸入與假設!D$28*(1-輸入與假設!D$29) -> 0.1256375 | E21: =E16*輸入與假設!E$28*(1-輸入與假設!E$29) -> 0.19305 | F21: =F16*輸入與假設!F$28*(1-輸入與假設!F$29) -> 0.250965 | G21: =G16*輸入與假設!G$28*(1-輸入與假設!G$29) -> 0.22120313
A22: 收現（期初 RPO 部分） | B22: US$bn | C22: =C16-C21 -> 8.0927175 | D22: =D16-D21 -> 25.001863 | E22: =E16-E21 -> 25.54695 | F22: =F16-F21 -> 24.845535 | G22: =G16-G21 -> 17.475047
A23: 模型期總營收（算力＋服務） | B23: US$bn | C23: =C19+輸入與假設!C$30 -> 8.413 | D23: =D19+輸入與假設!D$30 -> 26.1275 | E23: =E19+輸入與假設!E$30 -> 36.669415 | F23: =F19+輸入與假設!F$30 -> 42.363849 | G23: =G19+輸入與假設!G$30 -> 44.99393
A24: EBITDAR 率（EBITDA 率＋租金÷營收） | B24: % | C24: =輸入與假設!C$34+收支與融資!C11/MAX(0.01,C23) -> 0.74927731 | D24: =輸入與假設!D$34+收支與融資!D11/MAX(0.01,D23) -> 0.75576069 | E24: =輸入與假設!E$34+收支與融資!E11/MAX(0.01,E23) -> 0.74886365 | F24: =輸入與假設!F$34+收支與融資!F11/MAX(0.01,F23) -> 0.75592858 | G24: =輸入與假設!G$34+收支與融資!G11/MAX(0.01,G23) -> 0.76536086
A25: RPO 現金（可支應資本用途） | B25: US$bn | C25: =C22*C24 -> 6.0636896 | D25: =D22*D24 -> 18.895425 | E25: =E22*E24 -> 19.131182 | F25: =F22*F24 -> 18.78145 | G25: =G22*G24 -> 13.374717
A26: 新簽約現金 | B26: US$bn | C26: =C18*(1-輸入與假設!C$28*(1-輸入與假設!C$29))*C24 -> 0 | D26: =D18*(1-輸入與假設!D$28*(1-輸入與假設!D$29))*D24 -> 0 | E26: =E18*(1-輸入與假設!E$28*(1-輸入與假設!E$29))*E24 -> 6.7854123 | F26: =F18*(1-輸入與假設!F$28*(1-輸入與假設!F$29))*F24 -> 10.826919 | G26: =G18*(1-輸入與假設!G$28*(1-輸入與假設!G$29))*G24 -> 17.759402

Sheet 損益與評價
A1: 損益（類損益表）— 與資金模型同一組收入
A2: 算力收入、Cash CapEx、利息皆由前面分頁連結而來；改資金假設，此頁會跟著動
A4: 項目 | B4: 單位 | C4: FY26 | D4: FY27 | E4: FY28 | F4: FY29 | G4: FY30
A5: 損益表
A6: 算力收入 | B6: US$bn | C6: =產能與收入!C19 -> 8.113 | D6: =產能與收入!D19 -> 25.1275 | E6: =產能與收入!E19 -> 34.869416 | F6: =產能與收入!F19 -> 39.563848 | G6: =產能與收入!G19 -> 41.19393
A7: 非算力服務 | B7: US$bn | C7: =輸入與假設!C$30 -> 0.3 | D7: =輸入與假設!D$30 -> 1 | E7: =輸入與假設!E$30 -> 1.8 | F7: =輸入與假設!F$30 -> 2.8 | G7: =輸入與假設!G$30 -> 3.8
A8: 總營收 | B8: US$bn | C8: =C6+C7 -> 8.413 | D8: =D6+D7 -> 26.1275 | E8: =E6+E7 -> 36.669415 | F8: =F6+F7 -> 42.363849 | G8: =G6+G7 -> 44.99393
A9: 營業利益（EBIT） | B9: US$bn | C9: =C8*輸入與假設!C$34-輸入與假設!C$64 -> 0.20083667 | D9: =D8*輸入與假設!D$34-輸入與假設!D$64 -> 1.3505542 | E9: =E8*輸入與假設!E$34-輸入與假設!E$64 -> 2.6330376 | F9: =F8*輸入與假設!F$34-輸入與假設!F$64 -> 2.0815438 | G9: =G8*輸入與假設!G$34-輸入與假設!G$64 -> 0.19072117
A10: D&A | B10: US$bn | C10: =輸入與假設!C$64 -> 4.7628333 | D10: =輸入與假設!D$64 -> 14.456583 | E10: =輸入與假設!E$64 -> 20.102 | F10: =輸入與假設!F$64 -> 24.8195 | G10: =輸入與假設!G$64 -> 29.055333
A11: EBITDA | B11: US$bn | C11: =C9+C10 -> 4.96367 | D11: =D9+D10 -> 15.807137 | E11: =E9+E10 -> 22.735038 | F11: =F9+F10 -> 26.901044 | G11: =G9+G10 -> 29.246054
A12: 基礎股數（每年 +SBC 稀釋） | B12: bn | C12: =輸入與假設!$C$89 -> 0.587 | D12: =C12*(1+輸入與假設!$C$103) -> 0.59287 | E12: =D12*(1+輸入與假設!$C$103) -> 0.5987987 | F12: =E12*(1+輸入與假設!$C$103) -> 0.60478669 | G12: =F12*(1+輸入與假設!$C$103) -> 0.61083455
A13: 股數（含瀑布新股） | B13: bn | C13: =C12+收支與融資!C64 -> 0.587 | D13: =D12+收支與融資!D64 -> 0.59287 | E13: =E12+收支與融資!E64 -> 0.5987987 | F13: =F12+收支與融資!F64 -> 0.71121572 | G13: =G12+收支與融資!G64 -> 0.7822679
A14: 損益表（全年口徑；FY26＝1H 實際＋下半年模型；與 HTML 損益簡表一致）
A15: 1H26 實際營收（已實現） | B15: US$bn | C15: =輸入與假設!$C$128 -> 4.653 | D15: =0 -> 0 | E15: =0 -> 0 | F15: =0 -> 0 | G15: =0 -> 0
A16: 全年總營收 | B16: US$bn | C16: =C15+C8 -> 13.066 | D16: =D15+D8 -> 26.1275 | E16: =E15+E8 -> 36.669415 | F16: =F15+F8 -> 42.363849 | G16: =G15+G8 -> 44.99393
A17: 全年 GAAP 營業利益 | B17: US$bn | C17: =輸入與假設!$C$129+C9 -> 0.0078366667 | D17: =D9 -> 1.3505542 | E17: =E9 -> 2.6330376 | F17: =F9 -> 2.0815438 | G17: =G9 -> 0.19072117
A18: 全年 D&A | B18: US$bn | C18: =輸入與假設!$C$130+C10 -> 7.3028333 | D18: =D10 -> 14.456583 | E18: =E10 -> 20.102 | F18: =F10 -> 24.8195 | G18: =G10 -> 29.055333
A19: 全年 EBITDA | B19: US$bn | C19: =C17+C18 -> 7.31067 | D19: =D17+D18 -> 15.807137 | E19: =E17+E18 -> 22.735038 | F19: =F17+F18 -> 26.901044 | G19: =G17+G18 -> 29.246054
A21: 評價 — DCF、EV/EBITDA、加權目標價
A22: 營收、營業利益、D&A、EBITDA、股數引用『損益與評價』頁；Cash CapEx 與融資引用『收支與融資』頁
A24: 項目 | B24: 單位 | C24: FY26 | D24: FY27 | E24: FY28 | F24: FY29 | G24: FY30
A25: DCF（無槓桿自由現金流；起點為 2026-06-30）
A26: 現金 CapEx（2026-06-30 之後） | B26: US$bn | C26: =輸入與假設!C$63-收支與融資!C7 -> 19.16912 | D26: =輸入與假設!D$63-收支與融資!D7 -> 35.2682 | E26: =輸入與假設!E$63-收支與融資!E7 -> 27.0572 | F26: =輸入與假設!F$63-收支與融資!F7 -> 28.152 | G26: =輸入與假設!G$63-收支與融資!G7 -> 29.8724
A27: 比較基期營收 | B27: US$bn | C27: =5.131 -> 5.131 | D27: =4.653+損益與評價!C8 -> 13.066 | E27: =損益與評價!D8 -> 26.1275 | F27: =損益與評價!E8 -> 36.669415 | G27: =損益與評價!F8 -> 42.363849
A28: 營運資金變動 | B28: US$bn | C28: =輸入與假設!$C$97*MAX(0,損益與評價!C8-C27) -> 0.06564 | D28: =輸入與假設!$C$97*MAX(0,損益與評價!D8-D27) -> 0.26123 | E28: =輸入與假設!$C$97*MAX(0,損益與評價!E8-E27) -> 0.21083831 | F28: =輸入與假設!$C$97*MAX(0,損益與評價!F8-F27) -> 0.11388866 | G28: =輸入與假設!$C$97*MAX(0,損益與評價!G8-G27) -> 0.05260163
A29: 無槓桿 NOL 期初 | B29: US$bn | C29: =輸入與假設!$C$95 -> 4 | D29: =C31 -> 3.8393307 | E29: =D31 -> 2.7588873 | F29: =E31 -> 0.65245725 | G29: =F31 -> 0
A30: 本期動用（無槓桿） | B30: US$bn | C30: =MIN(C29,MAX(0,損益與評價!C9)*輸入與假設!$C$96) -> 0.16066933 | D30: =MIN(D29,MAX(0,損益與評價!D9)*輸入與假設!$C$96) -> 1.0804433 | E30: =MIN(E29,MAX(0,損益與評價!E9)*輸入與假設!$C$96) -> 2.1064301 | F30: =MIN(F29,MAX(0,損益與評價!F9)*輸入與假設!$C$96) -> 0.65245725 | G30: =MIN(G29,MAX(0,損益與評價!G9)*輸入與假設!$C$96) -> 0
A31: 無槓桿 NOL 期末 | B31: US$bn | C31: =C29-C30+MAX(0,-損益與評價!C9) -> 3.8393307 | D31: =D29-D30+MAX(0,-損益與評價!D9) -> 2.7588873 | E31: =E29-E30+MAX(0,-損益與評價!E9) -> 0.65245725 | F31: =F29-F30+MAX(0,-損益與評價!F9) -> 0 | G31: =G29-G30+MAX(0,-損益與評價!G9) -> 0
A32: 無槓桿所得稅（DCF 用） | B32: US$bn | C32: =MAX(0,損益與評價!C9-C30)*輸入與假設!$C$94 -> 0.00843514 | D32: =MAX(0,損益與評價!D9-D30)*輸入與假設!$C$94 -> 0.056723275 | E32: =MAX(0,損益與評價!E9-E30)*輸入與假設!$C$94 -> 0.11058758 | F32: =MAX(0,損益與評價!F9-F30)*輸入與假設!$C$94 -> 0.30010818 | G32: =MAX(0,損益與評價!G9-G30)*輸入與假設!$C$94 -> 0.040051445
A33: UFCF | B33: US$bn | C33: =損益與評價!C9-C32+損益與評價!C10-C26-C28 -> -14.279525 | D33: =損益與評價!D9-D32+損益與評價!D10-D26-D28 -> -19.779016 | E33: =損益與評價!E9-E32+損益與評價!E10-E26-E28 -> -4.6435883 | F33: =損益與評價!F9-F32+損益與評價!F10-F26-F28 -> -1.664953 | G33: =損益與評價!G9-G32+損益與評價!G10-G26-G28 -> -0.71899857
A34: 折現期數 | B34: 年 | C34: =輸入與假設!$C$110 -> 0.5 | D34: =輸入與假設!$D$110 -> 1.5 | E34: =輸入與假設!$E$110 -> 2.5 | F34: =輸入與假設!$F$110 -> 3.5 | G34: =輸入與假設!$G$110 -> 4.5
A35: 折現因子 | C35: =1/(1+輸入與假設!$C$91)^C34 -> 0.949158 | D35: =1/(1+輸入與假設!$C$91)^D34 -> 0.85509729 | E35: =1/(1+輸入與假設!$C$91)^E34 -> 0.77035792 | F35: =1/(1+輸入與假設!$C$91)^F34 -> 0.69401615 | G35: =1/(1+輸入與假設!$C$91)^G34 -> 0.62523977
A36: UFCF 現值 | B36: US$bn | C36: =C33*C35 -> -13.553525 | D36: =D33*D35 -> -16.912983 | E36: =E33*E35 -> -3.577225 | F36: =F33*F35 -> -1.1555043 | G36: =G33*G35 -> -0.4495465
A37: 五期 UFCF 現值合計 | C37: =SUM(C36:G36) -> -35.648784
A38: 常態化 FCF（FY30） | C38: =損益與評價!G9*(1-輸入與假設!$C$94)+損益與評價!G10-損益與評價!G10*輸入與假設!$C$93 -> 5.9617364
A39: 終值（Gordon） | C39: =IF(C47=1,0,C38*(1+輸入與假設!$C$92)/(輸入與假設!$C$91-輸入與假設!$C$92)) -> 76.757356
A40: 終值現值 | C40: =C39*G35 -> 47.991752
A41: 企業價值 EV | C41: =C37+C40 -> 12.342968
A42: 減：淨負債 | C42: =-輸入與假設!$C$90 -> -30
A43: 股權價值 | C43: =C41+C42 -> -17.657032
...
