Workbook

Sheet 導覽
A1: CoreWeave 收支與評價模型 — Excel 版 v4.4（更新 2026-09-25；與 HTML v4.4 同步；市價截至 2026-09-24 收盤）
A3: 這個活頁簿在回答什麼
A4: 一句話：CoreWeave 手上 $103.7bn 的合約（RPO）在 2030 年前能變成多少現金，而同一段時間要付出多少現金——
A5: 差額就是必須向外籌措的金額。所有分頁用同一組數字，改任何一個輸入，後面全部會跟著動。
A7: 分頁結構（依模組分組，分頁標籤顏色相同者為同一模組）
A8: 摘要 一頁摘要：結論、與市場共識的差異、現價隱含什麼、驗證點（v4.3；全部活公式）。
A9: 輸入與假設 所有可調參數（A 情境 → B 產能與收入 → C 利潤率 → D 支出 → E 融資 → F 評價 → G 1H 實際 → H 情境區間運算表 → I 市場共識 → J 季度追蹤輸入）。
A10: 各期收支 類現金流量：來源、用途、融資前缺口、期前融資瀑布。
A11: 季度追蹤 焦點季的模型／共識／指引／實際與差距（v4.4；由年度模型拆分，只用於追蹤；實際數填在輸入與假設 J 區）。
A12: 運營_產能與收入 合約排程 vs 機房產能 → 收入 → 現金；運營_站點：房東揭露與租金檢驗。
A13: 資產負債_既有債務／新債與新股／租賃承諾 類資產負債表：10-Q 債務明細、每期現金與總債務與股數、租賃承諾。
A14: 損益 類損益表（FY26＝1H 實際＋下半年模型）。
... A83: 舊版的透支利息（借款利息）與扣 NTM 缺口（借款本金）並非重複計費；v2.0 的差別是新債設上限、超出部分改以股權支應。瀑布位於「支出與資金」頁下方。

Sheet 摘要
A1: 一頁摘要 — 結論、與市場的差異、現價隱含什麼、驗證點（全部依輸入連動）
A2: ="模型端＝目前情境：" & CHOOSE(輸入與假設!$C$5,"保守 4.2 GW","基準 5.6 GW","積極 8 GW") & "（預設＝基準）；共識＝data/consensus_crwv_20260925.json（2026-09-25）" -> 模型端＝目前情境：基準 5.6 GW（預設＝基準）；共識＝data/consensus_crwv_20260925.json（2026-09-25）
A4: 1｜結論
A5: 結論｜評等代碼（1＝買進、0＝中立、−1＝賣出） | C5: =評價_DCF與目標價!C56 -> -1
A6: 結論｜評等 | C6: =CHOOSE(C5+2,"賣出","中立","買進") -> 賣出
A7: 結論｜點位（加權目標價） | B7: US$ | C7: =評價_DCF與目標價!C47 -> 47.938436
A8: 結論｜現價 | B8: US$ | C8: =輸入與假設!$C$98 -> 90.13
A9: 結論｜空間 | B9: % | C9: =C7/C8-1 -> -0.46811898
A10: 結論｜情境區間（下緣／上緣） | B10: US$ | C10: =評價_DCF與目標價!C61 -> 32.611289 | D10: =評價_DCF與目標價!D61 -> 71.685847
A11: 結論｜方法區間（下緣／上緣） | B11: US$ | C11: =評價_DCF與目標價!C63 -> 31.054079 | D11: =評價_DCF與目標價!D63 -> 47.938436
A12: 結論｜賣出門檻價 | B12: US$ | C12: =評價_DCF與目標價!$C$57 -> 76.6105
A13: 結論｜點位 − 賣出門檻 | B13: US$ | C13: =C7-C12 -> -28.672064
A14: 結論｜結論句 | C14: =C6&"：點位 $"&TEXT(C7,"0.0")&"，較現價 $"&TEXT(C8,"0.00")&" "&IF(C9>=0,"高","低")&" "&TEXT(ABS(C9)*100,"0")&"%；情境區間 $"&TEXT(C10,"0.0")&"–$"&TEXT(D10,"0.0")&"，方法區間 $"&TEXT(C11,"0.0")&"–$"&TEXT(D11,"0.0")&"；點位"&IF(C13<0,"低於","高於")&"賣出門檻 $"&TEXT(C12,"0.0")&" 達 $"&TEXT(ABS(C13),"0.0")&"。" -> 賣出：點位 $47.9，較現價 $90.13 低 47%；情境區間 $32.6–$71.7，方法區間 $31.1–$47.9；點位低於賣出門檻 $76.6 達 $28.7。
A15: 結論｜情境判斷句 | C15: =評價_DCF與目標價!C69 -> 情境區間上緣 $71.7 低於現價 $90.13：賣出在三個擴張情境下都成立。
A17: 2｜與市場的差異（模型：目前情境 vs 共識；FY26–FY28）
A18: 項目 | B18: 單位 | C18: FY26 | D18: FY27 | E18: FY28
A19: 差異｜營收｜模型 | B19: US$bn | C19: =損益!C26 -> 13.066 | D19: =損益!D26 -> 26.1275 | E19: =損益!E26 -> 36.669415
A20: 差異｜營收｜共識 | B20: US$bn | C20: =輸入與假設!$C$176 -> 12.882 | D20: =輸入與假設!$D$176 -> 26.376 | E20: =輸入與假設!$E$176 -> 42.55
A21: 差異｜營收｜差距 | B21: % | C21: =C19/C20-1 -> 0.014283496 | D21: =D19/D20-1 -> -0.0094214437 | E21: =E19/E20-1 -> -0.1382041
A22: 差異｜調整後 EBITDA｜模型 | B22: US$bn | C22: =輸入與假設!$C$148+損益!C19 -> 7.63067 | D22: =損益!D31 -> 15.807137 | E22: =損益!E31 -> 22.735038
A23: 差異｜調整後 EBITDA｜共識 | B23: US$bn | C23: =輸入與假設!$C$177 -> 7.574 | D23: =輸入與假設!$D$177 -> 16.656 | E23: =輸入與假設!$E$177 -> 28.857
A24: 差異｜調整後 EBITDA｜差距 | B24: % | C24: =C22/C23-1 -> 0.0074821759 | D24: =D22/D23-1 -> -0.050964367 | E24: =E22/E23-1 -> -0.21214826 | I24: FY26 模型＝1H 實際調整後 EBITDA（輸入與假設 G 區，報導轉述 [Verified]）＋2H 模型
A25: 差異｜EBITDA 率｜模型 | B25: % | C25: =C22/C19 -> 0.58400964 | D25: =D22/D19 -> 0.605 | E25: =E22/E19 -> 0.62
A26: 差異｜EBITDA 率｜共識 | B26: % | C26: =輸入與假設!$C$178 -> 0.588 | D26: =輸入與假設!$D$178 -> 0.632 | E26: =輸入與假設!$E$178 -> 0.678
A27: 差異｜EBITDA 率｜差距（百分點） | B27: pt | C27: =C25-C26 -> -0.0039903567 | D27: =D25-D26 -> -0.027 | E27: =E25-E26 -> -0.058 | I27: EBITDA 率以百分點列差距，不納入判斷
A28: 差異｜CapEx（毛額）｜模型 | B28: US$bn | C28: =輸入與假設!$C$132+輸入與假設!C$73 -> 36.975 | D28: =輸入與假設!D$73 -> 38.335 | E28: =輸入與假設!E$73 -> 29.41
A29: 差異｜CapEx（毛額）｜共識 | B29: US$bn | C29: =輸入與假設!$C$183 -> 35.953 | D29: =輸入與假設!$D$183 -> 46.476 | E29: =輸入與假設!$E$183 -> 50.129
A30: 差異｜CapEx（毛額）｜差距 | B30: % | C30: =C28/C29-1 -> 0.028426001 | D30: =D28/D29-1 -> -0.17516568 | E30: =E28/E29-1 -> -0.41331365 | I30: 共識 CapEx 口徑未揭露；FY26＝1H 實際毛額＋2H 模型毛額
A31: 差異｜淨負債｜模型 | B31: US$bn | C31: =資產負債_新債與新股!C22 -> 45.392496 | D31: =資產負債_新債與新股!D22 -> 71.885337 | E31: =資產負債_新債與新股!E22 -> 84.30991
A32: 差異｜淨負債｜共識 | B32: US$bn | C32: =輸入與假設!$C$185 -> 46.442 | D32: =輸入與假設!$D$185 -> 74.707 | E32: =輸入與假設!$E$185 -> 96.039
A33: 差異｜淨負債｜差距 | B33: % | C33: =C31/C32-1 -> -0.022598169 | D33: =D31/D32-1 -> -0.037769723 | E33: =E31/E32-1 -> -0.12212841 | I33: 共識淨負債不含租賃、口徑未揭露：只列不判斷
A34: 差異｜分歧項目（超過門檻者） | C34: =MID(IF(ABS(C21)>輸入與假設!$C$218,"、營收 "&IF(C21<0,"−","+")&TEXT(ABS(C21)*100,"0.0")&"%","")&IF(ABS(C24)>輸入與假設!$C$218,"、EBITDA "&IF(C24<0,"−","+")&TEXT(ABS(C24)*100,"0.0")&"%","")&IF(ABS(C30)>輸入與假設!$C$218,"、CapEx "&IF(C30<0,"−","+")&TEXT(ABS(C30)*100,"0.0")&"%",""),2,999) | D34: =MID(IF(ABS(D21)>輸入與假設!$C$218,"、營收 "&IF(D21<0,"−","+")&TEXT(ABS(D21)*100,"0.0")&"%","")&IF(ABS(D24)>輸入與假設!$C$218,"、EBITDA "&IF(D24<0,"−","+")&TEXT(ABS(D24)*100,"0.0")&"%","")&IF(ABS(D30)>輸入與假設!$C$218,"、CapEx "&IF(D30<0,"−","+")&TEXT(ABS(D30)*100,"0.0")&"%",""),2,999) -> EBITDA −5.1%、CapEx −17.5% | E34: =MID(IF(ABS(E21)>輸入與假設!$C$218,"、營收 "&IF(E21<0,"−","+")&TEXT(ABS(E21)*100,"0.0")&"%","")&IF(ABS(E24)>輸入與假設!$C$218,"、EBITDA "&IF(E24<0,"−","+")&TEXT(ABS(E24)*100,"0.0")&"%","")&IF(ABS(E30)>輸入與假設!$C$218,"、CapEx "&IF(E30<0,"−","+")&TEXT(ABS(E30)*100,"0.0")&"%",""),2,999) -> 營收 −13.8%、EBITDA −21.2%、CapEx −41.3% | I34: 營收、EBITDA、CapEx 任一項差距絕對值超過門檻即列出（與 HTML 判斷句同一規則）
A35: 差異｜分歧起始年（1＝FY26…3＝FY28；0＝無） | C35: =IF(C34<>"",1,IF(D34<>"",2,IF(E34<>"",3,0))) -> 2
A36: 差異｜判斷句 | C36: =CHOOSE(C35+1,"FY26–FY28 營收、EBITDA、CapEx 與共識差距皆在 "&IF(ROUND(ABS(輸入與假設!$C$218)*100,4)=INT(ROUND(ABS(輸入與假設!$C$218)*100,4)),TEXT(ROUND(ABS(輸入與假設!$C$218)*100,4),"0"),TEXT(ROUND(ABS(輸入與假設!$C$218)*100,4),"0.0"))&"%"&" 以內。","分歧始於 FY26（"&C34&"）"&"；FY27 "&IF(D34="","回到 "&IF(ROUND(ABS(輸入與假設!$C$218)*100,4)=INT(ROUND(ABS(輸入與假設!$C$218)*100,4)),TEXT(ROUND(ABS(輸入與假設!$C$218)*100,4),"0"),TEXT(ROUND(ABS(輸入與假設!$C$218)*100,4),"0.0"))&"%"&" 以內",D34)&"；FY28 "&IF(E34="","回到 "&IF(ROUND(ABS(輸入與假設!$C$218)*100,4)=INT(ROUND(ABS(輸入與假設!$C$218)*100,4)),TEXT(ROUND(ABS(輸入與假設!$C$218)*100,4),"0"),TEXT(ROUND(ABS(輸入與假設!$C$218)*100,4),"0.0"))&"%"&" 以內",E34)&"。","FY26 營收、EBITDA、CapEx 與共識差距在 "&IF(ROUND(ABS(輸入與假設!$C$218)*100,4)=INT(ROUND(ABS(輸入與假設!$C$218)*100,4)),TEXT(ROUND(ABS(輸入與假設!$C$218)*100,4),"0"),TEXT(ROUND(ABS(輸入與假設!$C$218)*100,4),"0.0"))&"%"&" 以內；分歧始於 FY27（"&D34&"）"&"；FY28 "&IF(E34="","回到 "&IF(ROUND(ABS(輸入與假設!$C$218)*100,4)=INT(ROUND(ABS(輸入與假設!$C$218)*100,4)),TEXT(ROUND(ABS(輸入與假設!$C$218)*100,4),"0"),TEXT(ROUND(ABS(輸入與假設!$C$218)*100,4),"0.0"))&"%"&" 以內",E34)&"。","FY26–FY27 營收、EBITDA、CapEx 與共識差距在 "&IF(ROUND(ABS(輸入與假設!$C$218)*100,4)=INT(ROUND(ABS(輸入與假設!$C$218)*100,4)),TEXT(ROUND(ABS(輸入與假設!$C$218)*100,4),"0"),TEXT(ROUND(ABS(輸入與假設!$C$218)*100,4),"0.0"))&"%"&" 以內；分歧始於 FY28（"&E34&"）。") -> FY26 營收、EBITDA、CapEx 與共識差距在 5% 以內；分歧始於 FY27（EBITDA −5.1%、CapEx −17.5%）；FY28 營收 −13.8%、EBITDA −21.2%、CapEx −41.3%。
A37: 差異原因｜FY26｜淨負債 | C37: =IF(ABS(C33)>輸入與假設!$C$218,"觀點","") | D37: =IF(ABS(C33)>輸入與假設!$C$218,"淨負債隨 CapEx 與融資需求而定（模型 CapEx 差距 "&IF(C30<0,"−","+")&TEXT(ABS(C30)*100,"#,##0.0")&"%"&"）；共識淨負債不含租賃、口徑未揭露","") | I37: C＝類型、D＝原因（差距超過門檻時顯示）
A38: 差異原因｜FY27｜EBITDA | C38: =IF(ABS(D24)>輸入與假設!$C$218,"觀點","") -> 觀點 | D38: =IF(ABS(D24)>輸入與假設!$C$218,"EBITDA 率 "&IF(D25<0,"−","")&TEXT(ABS(D25)*100,"#,##0.0")&"%"&" 對共識 "&IF(D26<0,"−","")&TEXT(ABS(D26)*100,"#,##0.0")&"%"&"：模型由 "&IF(輸入與假設!$C$36<0,"−","")&TEXT(ABS(輸入與假設!$C$36)*100,"#,##0")&"%"&" 線性爬升至 FY30 穩態 "&IF(輸入與假設!$C$37<0,"−","")&TEXT(ABS(輸入與假設!$C$37)*100,"#,##0")&"%"&"；營收差距 "&IF(D21<0,"−","+")&TEXT(ABS(D21)*100,"#,##0.0")&"%","") -> EBITDA 率 60.5% 對共識 63.2%：模型由 59% 線性爬升至 FY30 穩態 65%；營收差距 −0.9%
A39: 差異原因｜FY27｜CapEx | C39: =IF(ABS(D30)>輸入與假設!$C$218,"觀點","") -> 觀點 | D39: =IF(ABS(D30)>輸入與假設!$C$218,"CapEx 依新增 MW 計算：新增 "&IF(輸入與假設!D$66<0,"−","")&TEXT(ABS(輸入與假設!D$66),"#,##0")&" MW × 每 MW $"&IF(輸入與假設!D$57<0,"−","")&TEXT(ABS(輸入與假設!D$57),"#,##0")&"m（含次年預建）；共識口徑未揭露","") -> CapEx 依新增 MW 計算：新增 1,250 MW × 每 MW $34m（含次年預建）；共識口徑未揭露
A40: 差異原因｜FY27｜淨負債 | C40: =IF(ABS(D33)>輸入與假設!$C$218,"觀點","") | D40: =IF(ABS(D33)>輸入與假設!$C$218,"淨負債隨 CapEx 與融資需求而定（模型 CapEx 差距 "&IF(D30<0,"−","+")&TEXT(ABS(D30)*100,"#,##0.0")&"%"&"）；共識淨負債不含租賃、口徑未揭露","")
A41: 差異原因｜FY28｜營收 | C41: =IF(ABS(E21)>輸入與假設!$C$218,"觀點","") -> 觀點 | D41: =IF(ABS(E21)>輸入與假設!$C$218,"營收由模型 MW 路徑決定：FY28 年底 Accepted "&IF(輸入與假設!E$26<0,"−","")&TEXT(ABS(輸入與假設!E$26),"#,##0")&" MW（目前情境）；共識未揭露 MW 假設","") -> 營收由模型 MW 路徑決定：FY28 年底 Accepted 4,000 MW（目前情境）；共識未揭露 MW 假設
A42: 差異原因｜FY28｜EBITDA | C42: =IF(ABS(E24)>輸入與假設!$C$218,"觀點","") -> 觀點 | D42: =IF(ABS(E24)>輸入與假設!$C$218,"營收差距 "&IF(E21<0,"−","+")&TEXT(ABS(E21)*100,"#,##0.0")&"%"&"，加上 EBITDA 率 "&IF(E25<0,"−","")&TEXT(ABS(E25)*100,"#,##0.0")&"%"&" 對共識 "&IF(E26<0,"−","")&TEXT(ABS(E26)*100,"#,##0.0")&"%","") -> 營收差距 −13.8%，加上 EBITDA 率 62.0% 對共識 67.8%
...

Sheet 輸入與假設
A1: 輸入（依類別排序；點左側 ＋／− 展開或收合。藍字可改；黃底為最關鍵假設）
A2: A 情境 → B 產能與收入 → C 利潤率 → D 支出（CapEx／折舊／租賃／JV）→ E 融資 → F 評價 → G 參考：1H26 實際 → H 情境區間運算表 → I 市場共識 → J 季度追蹤輸入。灰底『▸』為明細子區，預設收合
A4: A｜情境與規模（管理層擴張力道）
A5: 情境選擇（1＝保守 4.2 GW、2＝基準 5.6 GW、3＝積極 8 GW） | C5: 2 | D5: =CHOOSE(C5,"保守 4.2 GW","基準 5.6 GW","積極 8 GW") -> 基準 5.6 GW | I5: 三情境只改變管理層的擴張力道；其餘假設相同。FY26–FY27 三者相同（年底 1,850／3,100 MW），FY28 起分歧
A6: ▸ 情境路徑明細（Accepted MW、爬坡比例、表外租金基準）
A7: Accepted MW 路徑 | B7: 單位 | C7: FY26 | D7: FY27 | E7: FY28 | F7: FY29 | G7: FY30 | I7: FY31 新增 MW
A8: 保守 4.2 GW | B8: MW | C8: 1850 | D8: 3100 | E8: 3800 | F8: 4200 | G8: 4200 | I8: 0 | J8: 只交付已簽約電力 4.2 GW（8/11 法說），不再新簽
A9: 基準 5.6 GW | B9: MW | C9: 1850 | D9: 3100 | E9: 4000 | F9: 4800 | G9: 5600 | I9: 500 | J9: 2027 年後每年約 +800 MW
A10: 積極 8 GW | B10: MW | C10: 1850 | D10: 3100 | E10: 4600 | F10: 6300 | G10: 8000 | I10: 1000 | J10: 公司目標 2030 ≥8 GW
A11: Billable／Accepted 爬坡比例 | B11: % | C11: 0.91891892 | D11: 0.93548387 | E11: 0.93478261 | F11: 0.93650794 | G11: 0.9375 | I11: 三情境共用
A12: 表外現金租金（積極路徑） | B12: US$bn | C12: 0.3 | D12: 1.6 | E12: 3 | F12: 4 | G12: 4.6 | I12: 其他情境依「新增 MW（相對 6/30 的 1,500 MW）」等比例縮放
A14: B｜產能與收入（RPO、MW、利用率、單價、簽約、信用）
A15: 6/30 RPO | B15: US$bn | C15: 103.7 | I15: 10-Q 103.7（backlog 104.2 含 0.5 其他）[Verified]
A16: Q3 初新增承諾 | B16: US$bn | C16: 25 | I16: 法說「>25」，尚未入 RPO [Interested-party]
A17: 五期認列比例（至 2030 末） | B17: % | C17: 0.84 | I17: 10-Q 桶 41／39／20 線性分攤後五期合計 84% [Derived]
A18: RPO 桶權重合計 | B18: % | C18: 0.84 | I18: 下方權重列的合計，用於歸一化
A19: 2025-12-31 主動電力 | B19: MW | C19: 850 | I19: Q4 2025 法說：年底 >850 MW、43 座資料中心 [Verified]
A20: 6/30 Billable MW | B20: MW | C20: 1350 | I20: 主動電力 1.5 GW 扣爬坡中 [Assumed]
A21: 收入用平均在役 MW（1=是） | C21: 1 | I21: 0＝用期末存量全期化。CRWV 交付後載（6 月 +300MW），建議 1
A22: 每 MW 年收入倍數（整體） | B22: % | C22: 1 | I22: 反向 DCF 與壓力測試用；預設 100%。以『目標搜尋』調整此格即可反解市價隱含單價
A23: 項目 | B23: 單位 | C23: FY26 | D23: FY27 | E23: FY28 | F23: FY29 | G23: FY30 | I23: 來源／標籤
A24: 模型期長度（年） | C24: 0.5 | D24: 1 | E24: 1 | F24: 1 | G24: 1 | I24: 勿改。FY26 模型期為 2026-07-01～12-31（0.5 年）。只用於容量上限、電力、維護三處年率換算 [Derived]
A25: RPO 桶權重 | B25: % | C25: 0.1025 | D25: 0.205 | E25: 0.2 | F25: 0.195 | G25: 0.1375 | H25: =SUM(C25:G25) -> 0.84 | I25: 10-Q 41%／24m、39%／25-48m、20%／49-78m 桶內線性分攤 [Derived]
A26: Accepted MW（期末主動電力） | B26: MW | C26: =CHOOSE(輸入與假設!$C$5,C8,C9,C10) -> 1850 | D26: =CHOOSE(輸入與假設!$C$5,D8,D9,D10) -> 3100 | E26: =CHOOSE(輸入與假設!$C$5,E8,E9,E10) -> 4000 | F26: =CHOOSE(輸入與假設!$C$5,F8,F9,F10) -> 4800 | G26: =CHOOSE(輸入與假設!$C$5,G8,G9,G10) -> 5600 | I26: ＝依 A 區情境選擇器
A27: Billable MW | B27: MW | C27: =ROUND(C26*C11,0) -> 1700 | D27: =ROUND(D26*D11,0) -> 2900 | E27: =ROUND(E26*E11,0) -> 3739 | F27: =ROUND(F26*F11,0) -> 4495 | G27: =ROUND(G26*G11,0) -> 5250 | I27: ＝Accepted × 爬坡比例（A 區）
A28: 利用率 | B28: % | C28: 0.95 | D28: 0.95 | E28: 0.94 | F28: 0.93 | G28: 0.92 | I28: 法說「近期產能實質售罄」，不擬合 100% [Assumed]
A29: 每 MW 年收入 | B29: US$bn/MW | C29: 0.0112 | D29: 0.0115 | E29: 0.0115 | F29: 0.011 | G29: 0.0105 | I29: 期末 ARR 18.5–19.5÷1.85GW≈10.0–10.5M/MW；7 月漲價 25% 只影響新約 [Derived]
A30: 新產能簽約率 | B30: % | C30: 1 | D30: 1 | E30: 0.9 | F30: 0.85 | G30: 0.8 | I30: 未被期初 RPO 占用的產能能賣掉的比例 [Assumed]
A31: 客戶違約率 | B31: % | C31: 0.005 | D31: 0.01 | E31: 0.015 | F31: 0.02 | G31: 0.025 | I31: 前三大客戶 72% 營收的定價，非預測 [Assumed]
A32: 回收率 | B32: % | C32: 0.5 | D32: 0.5 | E32: 0.5 | F32: 0.5 | G32: 0.5 | I32: [Assumed]
A33: 非算力服務營收 | B33: US$bn | C33: 0.3 | D33: 1 | E33: 1.8 | F33: 2.8 | G33: 3.8 | I33: 軟體／儲存／CPU／managed inference；損益營收與資金現金共用 [Derived]
A35: C｜利潤率（EBITDA 率單一來源；損益與資金共用）
A36: 起始 EBITDA 率（FY26） | B36: % | C36: 0.59 | I36: Q2 實際 Adj. EBITDA 率 58.6% [Verified]
A37: 穩態 EBITDA 率（FY30） | B37: % | C37: 0.65 | I37: 由下而上：每 MW 現金成本約 $3.2–3.6m／年收入 $10.9m → 67–71%；Q2 59% 含爬坡成本。基準 65%，敏感度 59%／70% [Derived]
A38: 項目 | B38: 單位 | C38: FY26 | D38: FY27 | E38: FY28 | F38: FY29 | G38: FY30 | I38: 來源／標籤
A39: EBITDA 率 | B39: % | C39: =輸入與假設!$C$36+(輸入與假設!$C$37-輸入與假設!$C$36)*0/4 -> 0.59 | D39: =輸入與假設!$C$36+(輸入與假設!$C$37-輸入與假設!$C$36)*1/4 -> 0.605 | E39: =輸入與假設!$C$36+(輸入與假設!$C$37-輸入與假設!$C$36)*2/4 -> 0.62 | F39: =輸入與假設!$C$36+(輸入與假設!$C$37-輸入與假設!$C$36)*3/4 -> 0.635 | G39: =輸入與假設!$C$36+(輸入與假設!$C$37-輸入與假設!$C$36)*4/4 -> 0.65 | I39: ＝起始＋(穩態−起始)×期數÷4（公式）
A40: 非算力服務現金 | B40: US$bn | C40: =輸入與假設!C$33*運營_產能與收入!C35 -> 0.22478319 | D40: =輸入與假設!D$33*運營_產能與收入!D35 -> 0.75576069 | E40: =輸入與假設!E$33*運營_產能與收入!E35 -> 1.3479546 | F40: =輸入與假設!F$33*運營_產能與收入!F35 -> 2.1166 | G40: =輸入與假設!G$33*運營_產能與收入!G35 -> 2.9083713 | I40: ＝服務營收 × EBITDAR 率（公式）
A41: ▸ 電力／維護 overlay（預設關閉；EBITDA 已含電費）
A42: 電力／維護 overlay（1=開） | C42: 0 | I42: EBITDA 率已含電費，開啟會重複扣除，僅供壓力測試
A43: 電價 | B43: $/MWh | C43: 60 | D43: 62 | E43: 64 | F43: 66 | G43: 68 | I43: overlay 用 [Assumed]
...

Sheet 各期收支
A1: 支出與資金 — 五層支出、四層來源、現金橋
A2: FY26 欄＝1H 實際（10-Q 現金流量表口徑）＋下半年模型；FY27 以後為純模型。瀑布以「融資前現金」決定需求並直接由各支出列加總，因此沒有循環參照
A4: 項目 | B4: 單位 | C4: FY26 | D4: FY27 | E4: FY28 | F4: FY29 | G4: FY30 | I4: 公式／來源說明
A5: 支出（五層）
A6: ① 毛 CapEx（認列，備忘） | B6: US$bn | C6: =輸入與假設!$C$132+輸入與假設!C$73 -> 36.975 | D6: =輸入與假設!D$73 -> 38.335 | E6: =輸入與假設!E$73 -> 29.41 | F6: =輸入與假設!F$73 -> 30.6 | G6: =輸入與假設!G$73 -> 32.47 | I6: FY26＝1H 實際認列 16.139＋2H 模型；對照公司全年指引 35–39。備忘列：用途合計採現金口徑，不用這一列
A7: 客戶預付率 | B7: % | C7: =輸入與假設!C$58 -> 0.08 | D7: =輸入與假設!D$58 -> 0.08 | E7: =輸入與假設!E$58 -> 0.08 | F7: =輸入與假設!F$58 -> 0.08 | G7: =輸入與假設!G$58 -> 0.08
A8: 客戶預付金額（抵減，2H 起） | B8: US$bn | C8: =輸入與假設!C$73*C7 -> 1.66688 | D8: =輸入與假設!D$73*D7 -> 3.0668 | E8: =輸入與假設!E$73*E7 -> 2.3528 | F8: =輸入與假設!F$73*F7 -> 2.448 | G8: =輸入與假設!G$73*G7 -> 2.5976 | I8: 1H 的預付已含在實際 CFO 內，不重複計入
A9: ① CapEx（用途用：1H 現金／2H 毛額） | B9: US$bn | C9: =輸入與假設!$C$131+輸入與假設!C$73 -> 34.953 | D9: =輸入與假設!D$73 -> 38.335 | E9: =輸入與假設!E$73 -> 29.41 | F9: =輸入與假設!F$73 -> 30.6 | G9: =輸入與假設!G$73 -> 32.47 | I9: 1H 採現金流量表的現金購置 14.117；2H 起採毛額，客戶預付在來源端抵回（避免重複計入）
A10: ② 在帳現金租金（備忘，1H 已含在 CFO） | B10: US$bn | C10: =輸入與假設!C$59 -> 1.04 | D10: =輸入與假設!D$59 -> 2.339 | E10: =輸入與假設!E$59 -> 2.306 | F10: =輸入與假設!F$59 -> 2.373 | G10: =輸入與假設!G$59 -> 2.289 | I10: 見『租賃與承諾』頁；2030 後尚有 19.023。FY26 欄僅 2H：1H 租金 0.748 已含在實際 CFO 內
A11: ② 表外現金租金（未起租） | B11: US$bn | C11: =輸入與假設!C$60 -> 0.3 | D11: =輸入與假設!D$60 -> 1.6 | E11: =輸入與假設!E$60 -> 2.4193548 | F11: =輸入與假設!F$60 -> 2.75 | G11: =輸入與假設!G$60 -> 2.9015385 | I11: 未起租 35.5＋單站上限 14.7＋355MW 造價計租的現金路徑
A12: 租金合計 | B12: US$bn | C12: =C10+C11 -> 1.34 | D12: =D10+D11 -> 3.939 | E12: =E10+E11 -> 4.7253548 | F12: =F10+F11 -> 5.123 | G12: =G10+G11 -> 5.1905385
A13: ③ 存量債務利息（備忘，1H 已含在 CFO） | B13: US$bn | C13: =輸入與假設!C$95 -> 1.8058963 | D13: =輸入與假設!D$95 -> 2.4660068 | E13: =輸入與假設!E$95 -> 2.0200947 | F13: =輸入與假設!F$95 -> 1.7324815 | G13: =輸入與假設!G$95 -> 1.4951385 | I13: 6/30 債務餘額的利息。FY26 全年利息＝1H 實際 1.176＋2H 1.8＝2.98（見下方備忘）
A14: 期初累積現金 | B14: US$bn | C14: =輸入與假設!$C$129 -> 3.127 | D14: =C41 -> 2 | E14: =D41 -> 2 | F14: =E41 -> 2 | G14: =F41 -> 2 | I14: FY26 自 2025-12-31 的 3.127 起算；之後＝前期期末累積現金
A15: 新債利率 | B15: % | C15: =IF(輸入與假設!$C$91=1,輸入與假設!C$94+MAX(0,輸入與假設!$C$90-450)/100*0.004,輸入與假設!C$94) -> 0.09 | D15: =IF(輸入與假設!$C$91=1,輸入與假設!D$94+MAX(0,輸入與假設!$C$90-450)/100*0.004,輸入與假設!D$94) -> 0.09 | E15: =IF(輸入與假設!$C$91=1,輸入與假設!E$94+MAX(0,輸入與假設!$C$90-450)/100*0.004,輸入與假設!E$94) -> 0.09 | F15: =IF(輸入與假設!$C$91=1,輸入與假設!F$94+MAX(0,輸入與假設!$C$90-450)/100*0.004,輸入與假設!F$94) -> 0.09 | G15: =IF(輸入與假設!$C$91=1,輸入與假設!G$94+MAX(0,輸入與假設!$C$90-450)/100*0.004,輸入與假設!G$94) -> 0.09 | I15: CDS 開關：＋MAX(0,CDS−450)×0.4bp/bp
A16: ③ 新債利息（瀑布） | B16: US$bn | C16: =C63 -> 0.56495231 | D16: =D63 -> 4.0708204 | E16: =E63 -> 5.5864719 | F16: =F63 -> 5.8690106 | G16: =G63 -> 6.515096 | I16: ＝新債利率×期間長度×(期初新債＋本期舉借)；見下方「期前融資瀑布」
A17: 利息合計 | B17: US$bn | C17: =C13+C16 -> 2.3708486 | D17: =D13+D16 -> 6.5368271 | E17: =E13+E16 -> 7.6065666 | F17: =F13+F16 -> 7.6014921 | G17: =G13+G16 -> 8.0102346
A18: ④ JV／策略投資出資 | B18: US$bn | C18: =輸入與假設!$C$133+輸入與假設!C$63 -> 1.938 | D18: =輸入與假設!D$63 -> 0.4 | E18: =輸入與假設!E$63 -> 0.3 | F18: =輸入與假設!F$63 -> 0.2 | G18: =輸入與假設!G$63 -> 0.2 | I18: FY26＝1H 實際 0.688（JV 0.550＋策略投資 0.138）＋2H 模型。10-Q 已承諾 1.7bn。CRWV 不發股息
A19: 電力（overlay） | B19: US$bn | C19: =IF(輸入與假設!$C$42=1,運營_產能與收入!C9*8760*輸入與假設!C$44*輸入與假設!C$43/1000000000*運營_產能與收入!C7,0) -> 0 | D19: =IF(輸入與假設!$C$42=1,運營_產能與收入!D9*8760*輸入與假設!D$44*輸入與假設!D$43/1000000000*運營_產能與收入!D7,0) -> 0 | E19: =IF(輸入與假設!$C$42=1,運營_產能與收入!E9*8760*輸入與假設!E$44*輸入與假設!E$43/1000000000*運營_產能與收入!E7,0) -> 0 | F19: =IF(輸入與假設!$C$42=1,運營_產能與收入!F9*8760*輸入與假設!F$44*輸入與假設!F$43/1000000000*運營_產能與收入!F7,0) -> 0 | G19: =IF(輸入與假設!$C$42=1,運營_產能與收入!G9*8760*輸入與假設!G$44*輸入與假設!G$43/1000000000*運營_產能與收入!G7,0) -> 0 | I19: ＝Accepted MW×8760×PUE×電價÷1e9×期間係數。CRWV 電費多經房東轉嫁，預設關閉
A20: 維護（overlay） | B20: US$bn | C20: =IF(輸入與假設!$C$42=1,運營_產能與收入!C9*輸入與假設!C$45/1000*運營_產能與收入!C7,0) -> 0 | D20: =IF(輸入與假設!$C$42=1,運營_產能與收入!D9*輸入與假設!D$45/1000*運營_產能與收入!D7,0) -> 0 | E20: =IF(輸入與假設!$C$42=1,運營_產能與收入!E9*輸入與假設!E$45/1000*運營_產能與收入!E7,0) -> 0 | F20: =IF(輸入與假設!$C$42=1,運營_產能與收入!F9*輸入與假設!F$45/1000*運營_產能與收入!F7,0) -> 0 | G20: =IF(輸入與假設!$C$42=1,運營_產能與收入!G9*輸入與假設!G$45/1000*運營_產能與收入!G7,0) -> 0
A21: ⑤ 排程還本（10-Q 本金表） | B21: US$bn | C21: =輸入與假設!$C$135+IF(輸入與假設!$C$82=1,輸入與假設!C$93,0) -> 9.632 | D21: =IF(輸入與假設!$C$82=1,輸入與假設!D$93,0) -> 6.184 | E21: =IF(輸入與假設!$C$82=1,輸入與假設!E$93,0) -> 4.416 | F21: =IF(輸入與假設!$C$82=1,輸入與假設!F$93,0) -> 2.421 | G21: =IF(輸入與假設!$C$82=1,輸入與假設!G$93,0) -> 3.221 | I21: FY26＝1H 實際還款 5.219＋2H 到期表 4.413
A22: ⑥ capped call 支出（1H 實際） | B22: US$bn | C22: =輸入與假設!$C$136 -> 0.492 | D22: =0 -> 0 | E22: =0 -> 0 | F22: =0 -> 0 | G22: =0 -> 0 | I22: Q2 4.0bn 可轉債的 capped call 現金支出
A23: 用途合計（現金口徑） | B23: US$bn | C23: =C9+C12+C17+C18+C19+C20+C21+C22 -> 50.725849 | D23: =D9+D12+D17+D18+D19+D20+D21+D22 -> 55.394827 | E23: =E9+E12+E17+E18+E19+E20+E21+E22 -> 46.457921 | F23: =F9+F12+F17+F18+F19+F20+F21+F22 -> 45.945492 | G23: =G9+G12+G17+G18+G19+G20+G21+G22 -> 49.091773 | I23: FY26 的 1H 部分採 10-Q 現金流量表口徑（現金購置、還款、JV、capped call）；1H 的利息與租金已含在 CFO 內，不重複列
A24: 來源（四層）
A25: Ⓐ0 1H26 實際營運現金流（CFO） | B25: US$bn | C25: =輸入與假設!$C$130 -> 3.663 | D25: =0 -> 0 | E25: =0 -> 0 | F25: =0 -> 0 | G25: =0 -> 0 | I25: 10-Q 實際值，取代模型推算；已含 1H 的利息、租金與客戶預付
A26: Ⓐ RPO 現金（2H 起） | B26: US$bn | C26: =運營_產能與收入!C36 -> 6.0636896 | D26: =運營_產能與收入!D36 -> 18.895425 | E26: =運營_產能與收入!E36 -> 19.131182 | F26: =運營_產能與收入!F36 -> 18.78145 | G26: =運營_產能與收入!G36 -> 13.374717
A27: Ⓑ 新簽約現金 | B27: US$bn | C27: =運營_產能與收入!C37 -> 0 | D27: =運營_產能與收入!D37 -> 0 | E27: =運營_產能與收入!E37 -> 6.7854123 | F27: =運營_產能與收入!F37 -> 10.826919 | G27: =運營_產能與收入!G37 -> 17.759402
A28: Ⓒ 非算力服務現金 | B28: US$bn | C28: =輸入與假設!C$40 -> 0.22478319 | D28: =輸入與假設!D$40 -> 0.75576069 | E28: =輸入與假設!E$40 -> 1.3479546 | F28: =輸入與假設!F$40 -> 2.1166 | G28: =輸入與假設!G$40 -> 2.9083713
A29: Ⓓ 客戶預付（2H 起） | B29: US$bn | C29: =C8 -> 1.66688 | D29: =D8 -> 3.0668 | E29: =E8 -> 2.3528 | F29: =F8 -> 2.448 | G29: =G8 -> 2.5976
A30: 營運來源合計 | B30: US$bn | C30: =C25+C26+C27+C28+C29 -> 11.618353 | D30: =D25+D26+D27+D28+D29 -> 22.717986 | E30: =E25+E26+E27+E28+E29 -> 29.617349 | F30: =F25+F26+F27+F28+F29 -> 34.172969 | G30: =G25+G26+G27+G28+G29 -> 36.64009
A31: Ⓔ 股權／可轉債（融資） | B31: US$bn | C31: =輸入與假設!$C$137+IF(輸入與假設!$C$79=1,輸入與假設!$C$78,0) -> 9.182 | D31: =0 -> 0 | E31: =0 -> 0 | F31: =0 -> 0 | G31: =0 -> 0 | I31: FY26＝1H 私募股權 2.982＋2H 可轉債淨現金 3.2＋ATM 上限 2.8
A32: Ⓕ 1H26 實際借款（融資） | B32: US$bn | C32: =輸入與假設!$C$134 -> 16.747 | D32: =0 -> 0 | E32: =0 -> 0 | F32: =0 -> 0 | G32: =0 -> 0 | I32: 10-Q：H1 借款 16.747。1H 的缺口實際上就是靠舉債填補的
A33: Ⓖ 瀑布：新債（額度＋資產層） | B33: US$bn | C33: =C58 -> 12.554496 | D33: =D58 -> 32.676842 | E33: =E58 -> 16.840572 | F33: =F58 -> 3.1393189 | G33: =G58 -> 7.1787275 | I33: 見下方「期前融資瀑布」
A34: Ⓗ 瀑布：股權募資 | B34: US$bn | C34: =C61 -> 0 | D34: =D61 -> 0 | E34: =E61 -> 0 | F34: =F61 -> 8.6332038 | G34: =G61 -> 5.2729553 | I34: 債務用罄後的殘差；每年不超過股權吸收上限
A35: Ⓘ 瀑布：高息債（股權上限溢出） | B35: US$bn | C35: =C62 -> 0 | D35: =D62 -> 0 | E35: =E62 -> 0 | F35: =F62 -> 0 | G35: =G62 -> 0 | I35: 股權超過每年上限的部分；不受 backlog 上限約束
A36: 總來源（含融資） | B36: US$bn | C36: =C30+C31+C32+C33+C34+C35 -> 50.101849 | D36: =D30+D31+D32+D33+D34+D35 -> 55.394827 | E36: =E30+E31+E32+E33+E34+E35 -> 46.457921 | F36: =F30+F31+F32+F33+F34+F35 -> 45.945492 | G36: =G30+G31+G32+G33+G34+G35 -> 49.091773
A37: 缺口與現金橋
A38: 1H 其他／受限現金調節 | B38: US$bn | C38: =輸入與假設!$C$77-(輸入與假設!$C$129+輸入與假設!$C$130+輸入與假設!$C$134+輸入與假設!$C$137-輸入與假設!$C$131-輸入與假設!$C$133-輸入與假設!$C$135-輸入與假設!$C$136) -> -0.503 | D38: =0 -> 0 | E38: =0 -> 0 | F38: =0 -> 0 | G38: =0 -> 0 | I38: 使 1H 實際流量接回 6/30 現金餘額；差額來自受限現金重分類與未逐項列出的項目
A39: 營運缺口（不含融資、不含還本） | B39: US$bn | C39: =C30-(C23-C21-C22) -> -28.983496 | D39: =D30-(D23-D21-D22) -> -26.492842 | E39: =E30-(E23-E21-E22) -> -12.424572 | F39: =F30-(F23-F21-F22) -> -9.3515227 | G39: =G30-(G23-G21-G22) -> -9.2306828 | I39: 本業能不能自給：營運來源 −（用途 − 排程還本 − capped call）
A40: 期間缺口（含融資） | B40: US$bn | C40: =C36-C23+C38 -> -1.127 | D40: =D36-D23+D38 -> 0 | E40: =E36-E23+E38 -> 0 | F40: =F36-F23+F38 -> 0 | G40: =G36-G23+G38 -> 0
A41: 期末累積現金 | B41: US$bn | C41: =C14+C40 -> 2 | D41: =D14+D40 -> 2 | E41: =E14+E40 -> 2 | F41: =F14+F40 -> 2 | G41: =G14+G40 -> 2 | I41: 期前融資：每期末不低於最低現金
...

Sheet 季度追蹤
A1: 季度追蹤 — 焦點季的模型／共識／指引／實際與差距（由年度模型拆分；只用於追蹤，不影響年度數字與目標價）
A2: 設定與實際數在『輸入與假設』J 區，共識在 I 區；缺資料顯示「不適用」，實際數空白＝待公布。差距超過門檻的項目附差異原因（拆法＝所屬期間合計差距在門檻內）。第 2 區為 6 季路徑與拆分明細（預設收合）。
A4: 1｜焦點季（『輸入與假設』J 區選擇）：模型／共識／指引／實際與差距
A5: 指標 | B5: 單位 | C5: 模型 | D5: 共識 | E5: 模型 vs 共識 | F5: 指引（低） | G5: 指引（高） | H5: 模型 vs 指引中點 | I5: 實際 | J5: 實際 vs 模型 | K5: 實際 vs 共識 | L5: 實際 vs 指引中點
A6: 焦點｜營收 | B6: US$bn | C6: =INDEX($C$22:$H$22,輸入與假設!$C$223) -> 3.6626667 | D6: =INDEX($C$32:$H$32,輸入與假設!$C$223) -> 3.541 | E6: =INDEX($C$48:$H$48,輸入與假設!$C$223) -> 0.034359409 | F6: =INDEX($C$36:$H$36,輸入與假設!$C$223) -> 3.45 | G6: =INDEX($C$37:$H$37,輸入與假設!$C$223) -> 3.6 | H6: =INDEX($C$49:$H$49,輸入與假設!$C$223) -> 0.039054374 | I6: =IF(ISNUMBER(INDEX($C$42:$H$42,輸入與假設!$C$223)),INDEX($C$42:$H$42,輸入與假設!$C$223),"待公布") -> 待公布 | J6: =INDEX($C$50:$H$50,輸入與假設!$C$223) | K6: =INDEX($C$51:$H$51,輸入與假設!$C$223) | L6: =INDEX($C$52:$H$52,輸入與假設!$C$223)
A7: 焦點｜調整後 EBITDA | B7: US$bn | C7: =INDEX($C$28:$H$28,輸入與假設!$C$223) -> 2.1509613 | D7: =INDEX($C$33:$H$33,輸入與假設!$C$223) -> 2.047 | E7: =INDEX($C$53:$H$53,輸入與假設!$C$223) -> 0.050787131 | F7: 不適用 | G7: 不適用 | H7: =INDEX($C$54:$H$54,輸入與假設!$C$223) -> 不適用 | I7: =IF(ISNUMBER(INDEX($C$43:$H$43,輸入與假設!$C$223)),INDEX($C$43:$H$43,輸入與假設!$C$223),"待公布") -> 待公布 | J7: =INDEX($C$55:$H$55,輸入與假設!$C$223) | K7: =INDEX($C$56:$H$56,輸入與假設!$C$223) | L7: =INDEX($C$57:$H$57,輸入與假設!$C$223)
A8: 焦點｜EBITDA 率 | B8: % | C8: =INDEX($C$27:$H$27,輸入與假設!$C$223) -> 0.58726645 | D8: =INDEX($C$34:$H$34,輸入與假設!$C$223) -> 0.57808529 | E8: =INDEX($C$58:$H$58,輸入與假設!$C$223) -> 0.009181165 | F8: 不適用 | G8: 不適用 | H8: =INDEX($C$59:$H$59,輸入與假設!$C$223) -> 不適用 | I8: =IF(ISNUMBER(INDEX($C$44:$H$44,輸入與假設!$C$223)),INDEX($C$44:$H$44,輸入與假設!$C$223),"待公布") -> 待公布 | J8: =INDEX($C$60:$H$60,輸入與假設!$C$223) | K8: =INDEX($C$61:$H$61,輸入與假設!$C$223) | L8: =INDEX($C$62:$H$62,輸入與假設!$C$223)
A9: 焦點｜調整後營業利益 | B9: US$bn | C9: =INDEX($C$30:$H$30,輸入與假設!$C$223) -> -0.013413743 | D9: 不適用 | E9: =INDEX($C$63:$H$63,輸入與假設!$C$223) -> 不適用 | F9: =INDEX($C$38:$H$38,輸入與假設!$C$223) -> 0.2 | G9: =INDEX($C$39:$H$39,輸入與假設!$C$223) -> 0.26 | H9: =INDEX($C$64:$H$64,輸入與假設!$C$223) -> -1.0583206 | I9: =IF(ISNUMBER(INDEX($C$45:$H$45,輸入與假設!$C$223)),INDEX($C$45:$H$45,輸入與假設!$C$223),"待公布") -> 待公布 | J9: =INDEX($C$65:$H$65,輸入與假設!$C$223) | K9: =INDEX($C$66:$H$66,輸入與假設!$C$223) | L9: =INDEX($C$67:$H$67,輸入與假設!$C$223)
A10: 焦點｜CapEx（毛額） | B10: US$bn | C10: =INDEX($C$31:$H$31,輸入與假設!$C$223) -> 10.418 | D10: 不適用 | E10: =INDEX($C$68:$H$68,輸入與假設!$C$223) -> 不適用 | F10: =INDEX($C$40:$H$40,輸入與假設!$C$223) -> 11.5 | G10: =INDEX($C$41:$H$41,輸入與假設!$C$223) -> 13.5 | H10: =INDEX($C$69:$H$69,輸入與假設!$C$223) -> -0.16656 | I10: =IF(ISNUMBER(INDEX($C$46:$H$46,輸入與假設!$C$223)),INDEX($C$46:$H$46,輸入與假設!$C$223),"待公布") -> 待公布 | J10: =INDEX($C$70:$H$70,輸入與假設!$C$223) | K10: =INDEX($C$71:$H$71,輸入與假設!$C$223) | L10: =INDEX($C$72:$H$72,輸入與假設!$C$223)
A11: 焦點｜季末 Accepted MW | B11: MW | C11: =INDEX($C$19:$H$19,輸入與假設!$C$223) -> 1675 | D11: 不適用 | E11: =INDEX($C$73:$H$73,輸入與假設!$C$223) -> 不適用 | F11: 不適用 | G11: 不適用 | H11: =INDEX($C$74:$H$74,輸入與假設!$C$223) -> 不適用 | I11: =IF(ISNUMBER(INDEX($C$47:$H$47,輸入與假設!$C$223)),INDEX($C$47:$H$47,輸入與假設!$C$223),"待公布") -> 待公布 | J11: =INDEX($C$75:$H$75,輸入與假設!$C$223) | K11: =INDEX($C$76:$H$76,輸入與假設!$C$223) | L11: =INDEX($C$77:$H$77,輸入與假設!$C$223)
A12: 焦點｜季度 | C12: =INDEX($C$16:$H$16,輸入與假設!$C$223) -> Q3'26
A13: 焦點｜差異原因 | C13: =IF(INDEX($C$112:$H$112,輸入與假設!$C$223)="","無（差距皆在 "&IF(ROUND(ABS(輸入與假設!$C$218)*100,4)=INT(ROUND(ABS(輸入與假設!$C$218)*100,4)),TEXT(ROUND(ABS(輸入與假設!$C$218)*100,4),"0"),TEXT(ROUND(ABS(輸入與假設!$C$218)*100,4),"0.0"))&"%"&" 以內）",INDEX($C$112:$H$112,輸入與假設!$C$223)) -> 調整後 EBITDA vs 共識 +5.1%：拆法（2H26 合計差距 +0.4%）；調整後營業利益 vs 指引中點 −105.8%：已知限制（模型車隊折舊 2.16 高於最新一季實際 1.39，營業利益因此偏低；待辦 6 修正）；CapEx（毛額） vs 指引中點 −16.7%：拆法（2H26 合計差距 −0.1%）
A15: 2｜6 季路徑、共識、指引、實際與差距（明細；第 1 區以焦點季引用本區）
A16: 項目 | B16: 單位 | C16: Q3'26 | D16: Q4'26 | E16: Q1'27 | F16: Q2'27 | G16: Q3'27 | H16: Q4'27
A17: 所屬期間 | C17: =輸入與假設!C$222 -> 1 | D17: =輸入與假設!D$222 -> 1 | E17: =輸入與假設!E$222 -> 2 | F17: =輸入與假設!F$222 -> 2 | G17: =輸入與假設!G$222 -> 2 | H17: =輸入與假設!H$222 -> 2 | J17: 1＝2H26、2＝FY27
A18: 季序 | C18: 1 | D18: 2 | E18: 3 | F18: 4 | G18: 5 | H18: 6 | J18: EBITDA 率直線的 x 軸
A19: 季末 Accepted MW（模型） | B19: MW | C19: =輸入與假設!$C$225+(輸入與假設!C$26-輸入與假設!$C$225)*1/2 -> 1675 | D19: =輸入與假設!$C$225+(輸入與假設!C$26-輸入與假設!$C$225)*2/2 -> 1850 | E19: =輸入與假設!C$26+(輸入與假設!D$26-輸入與假設!C$26)*1/4 -> 2162.5 | F19: =輸入與假設!C$26+(輸入與假設!D$26-輸入與假設!C$26)*2/4 -> 2475 | G19: =輸入與假設!C$26+(輸入與假設!D$26-輸入與假設!C$26)*3/4 -> 2787.5 | H19: =輸入與假設!C$26+(輸入與假設!D$26-輸入與假設!C$26)*4/4 -> 3100 | J19: 期初與期末 Accepted 之間線性內插；第 1 期起點見 J 區
A20: 平均在役 MW（Billable，拆分依據） | B20: MW | C20: =輸入與假設!$C$20+(輸入與假設!C$27-輸入與假設!$C$20)*1/4 -> 1437.5 | D20: =輸入與假設!$C$20+(輸入與假設!C$27-輸入與假設!$C$20)*3/4 -> 1612.5 | E20: =輸入與假設!C$27+(輸入與假設!D$27-輸入與假設!C$27)*1/8 -> 1850 | F20: =輸入與假設!C$27+(輸入與假設!D$27-輸入與假設!C$27)*3/8 -> 2150 | G20: =輸入與假設!C$27+(輸入與假設!D$27-輸入與假設!C$27)*5/8 -> 2450 | H20: =輸入與假設!C$27+(輸入與假設!D$27-輸入與假設!C$27)*7/8 -> 2750 | J20: 期初與期末 Billable 之間線性內插的季平均
A21: 季內新增 Accepted MW | B21: MW | C21: =C19-輸入與假設!$C$225 -> 175 | D21: =D19-C19 -> 175 | E21: =E19-輸入與假設!C$26 -> 312.5 | F21: =F19-E19 -> 312.5 | G21: =G19-F19 -> 312.5 | H21: =H19-G19 -> 312.5 | J21: CapEx 拆分依據
A22: 營收（模型） | B22: US$bn | C22: =輸入與假設!$C$224+1*(損益!C8-2*輸入與假設!$C$224)/3 -> 3.6626667 | D22: =輸入與假設!$C$224+2*(損益!C8-2*輸入與假設!$C$224)/3 -> 4.7503333 | E22: =損益!D8*E20/(E20+F20+G20+H20) -> 5.2538995 | F22: =損益!D8*F20/(E20+F20+G20+H20) -> 6.1058832 | G22: =損益!D8*G20/(E20+F20+G20+H20) -> 6.9578668 | H22: =損益!D8*H20/(E20+F20+G20+H20) -> 7.8098505 | J22: 拆分方法見『輸入與假設』J 區與 HTML「拆分方法」
A23: EBITDA 率直線｜各期營收合計 S | C23: =C22+D22 -> 8.413 | D23: =E22+F22+G22+H22 -> 26.1275 | J23: 欄＝期間（2H26、FY27）
A24: EBITDA 率直線｜營收 × 季序合計 T | C24: =C22*C18+D22*D18 -> 13.163333 | D24: =E22*E18+F22*F18+G22*G18+H22*H18 -> 121.83367 | J24: 欄＝期間（2H26、FY27）
A25: EBITDA 率直線｜年度 EBITDA E | C25: =損益!C19 -> 4.96367 | D25: =損益!D19 -> 15.807137 | J25: 欄＝期間（2H26、FY27）
A26: EBITDA 率直線｜截距 a／斜率 b | C26: =(C25*D24-C24*D25)/(C23*D24-C24*D23) -> 0.58242525 | D26: =(C23*D25-D23*C25)/(C23*D24-C24*D23) -> 0.0048412061 | J26: 解兩式：Σ營收×(a＋b×季序)＝各期年度 EBITDA
A27: EBITDA 率（模型） | B27: % | C27: =$C$26+$D$26*C18 -> 0.58726645 | D27: =$C$26+$D$26*D18 -> 0.59210766 | E27: =$C$26+$D$26*E18 -> 0.59694886 | F27: =$C$26+$D$26*F18 -> 0.60179007 | G27: =$C$26+$D$26*G18 -> 0.60663128 | H27: =$C$26+$D$26*H18 -> 0.61147248 | J27: 跨季一條直線，季度 EBITDA 加總＝年度
A28: 調整後 EBITDA（模型） | B28: US$bn | C28: =C22*C27 -> 2.1509613 | D28: =D22*D27 -> 2.8127087 | E28: =E22*E27 -> 3.1363093 | F28: =F22*F27 -> 3.6744598 | G28: =G22*G27 -> 4.2208596 | H28: =H22*H27 -> 4.7755087
A29: 車隊折舊（模型） | B29: US$bn | C29: =(輸入與假設!C$71+輸入與假設!C$69*1/4)/輸入與假設!$C$51*輸入與假設!C$24/2 -> 2.164375 | D29: =(輸入與假設!C$71+輸入與假設!C$69*3/4)/輸入與假設!$C$51*輸入與假設!C$24/2 -> 2.5984583 | E29: =(輸入與假設!D$71+輸入與假設!D$69*1/8)/輸入與假設!$C$51*輸入與假設!D$24/4 -> 3.0151615 | F29: =(輸入與假設!D$71+輸入與假設!D$69*3/8)/輸入與假設!$C$51*輸入與假設!D$24/4 -> 3.4144844 | G29: =(輸入與假設!D$71+輸入與假設!D$69*5/8)/輸入與假設!$C$51*輸入與假設!D$24/4 -> 3.8138073 | H29: =(輸入與假設!D$71+輸入與假設!D$69*7/8)/輸入與假設!$C$51*輸入與假設!D$24/4 -> 4.2131302 | J29: 依期內平均 PP&E（與年度車隊折舊公式相同）
A30: 調整後營業利益（模型） | B30: US$bn | C30: =C28-C29 -> -0.013413743 | D30: =D28-D29 -> 0.21425041 | E30: =E28-E29 -> 0.12114785 | F30: =F28-F29 -> 0.25997547 | G30: =G28-G29 -> 0.40705235 | H30: =H28-H29 -> 0.56237849 | J30: ＝調整後 EBITDA − 車隊折舊（未扣 SBC）
A31: CapEx（毛額）（模型） | B31: US$bn | C31: =IF((C21+D21)>0,輸入與假設!C$73*C21/(C21+D21),輸入與假設!C$73/2) -> 10.418 | D31: =IF((C21+D21)>0,輸入與假設!C$73*D21/(C21+D21),輸入與假設!C$73/2) -> 10.418 | E31: =IF((E21+F21+G21+H21)>0,輸入與假設!D$73*E21/(E21+F21+G21+H21),輸入與假設!D$73/4) -> 9.58375 | F31: =IF((E21+F21+G21+H21)>0,輸入與假設!D$73*F21/(E21+F21+G21+H21),輸入與假設!D$73/4) -> 9.58375 | G31: =IF((E21+F21+G21+H21)>0,輸入與假設!D$73*G21/(E21+F21+G21+H21),輸入與假設!D$73/4) -> 9.58375 | H31: =IF((E21+F21+G21+H21)>0,輸入與假設!D$73*H21/(E21+F21+G21+H21),輸入與假設!D$73/4) -> 9.58375 | J31: 依季內新增 Accepted MW
A32: 共識｜營收 | B32: US$bn | C32: =IF(ISNUMBER(輸入與假設!$C$194),輸入與假設!$C$194,"不適用") -> 3.541 | D32: =IF(ISNUMBER(輸入與假設!$D$194),輸入與假設!$D$194,"不適用") -> 4.706 | E32: 不適用 | F32: 不適用 | G32: 不適用 | H32: 不適用 | J32: I 區季度共識 [Interested-party]
A33: 共識｜調整後 EBITDA | B33: US$bn | C33: =IF(ISNUMBER(輸入與假設!$C$195),輸入與假設!$C$195,"不適用") -> 2.047 | D33: =IF(ISNUMBER(輸入與假設!$D$195),輸入與假設!$D$195,"不適用") -> 2.897 | E33: 不適用 | F33: 不適用 | G33: 不適用 | H33: 不適用 | J33: I 區季度共識 [Interested-party]
A34: 共識｜EBITDA 率 [Derived] | B34: % | C34: =IF(AND(ISNUMBER(輸入與假設!$C$195),ISNUMBER(輸入與假設!$C$194)),輸入與假設!$C$195/輸入與假設!$C$194,"不適用") -> 0.57808529 | D34: =IF(AND(ISNUMBER(輸入與假設!$D$195),ISNUMBER(輸入與假設!$D$194)),輸入與假設!$D$195/輸入與假設!$D$194,"不適用") -> 0.61559711 | E34: 不適用 | F34: 不適用 | G34: 不適用 | H34: 不適用 | J34: ＝共識 EBITDA ÷ 共識營收
A35: 共識 EBIT（口徑未揭露） | B35: US$bn | C35: =IF(ISNUMBER(輸入與假設!$C$196),輸入與假設!$C$196,"不適用") -> 0.2408 | D35: =IF(ISNUMBER(輸入與假設!$D$196),輸入與假設!$D$196,"不適用") -> 0.6805 | E35: 不適用 | F35: 不適用 | G35: 不適用 | H35: 不適用 | J35: 口徑未揭露：只列不比較
A36: 指引｜營收（低） | B36: US$bn | C36: =IF(ISNUMBER(輸入與假設!C$234),輸入與假設!C$234,"不適用") -> 3.45 | D36: =IF(ISNUMBER(輸入與假設!D$234),輸入與假設!D$234,"不適用") -> 不適用 | E36: =IF(ISNUMBER(輸入與假設!E$234),輸入與假設!E$234,"不適用") -> 不適用 | F36: =IF(ISNUMBER(輸入與假設!F$234),輸入與假設!F$234,"不適用") -> 不適用 | G36: =IF(ISNUMBER(輸入與假設!G$234),輸入與假設!G$234,"不適用") -> 不適用 | H36: =IF(ISNUMBER(輸入與假設!H$234),輸入與假設!H$234,"不適用") -> 不適用
A37: 指引｜營收（高） | B37: US$bn | C37: =IF(ISNUMBER(輸入與假設!C$235),輸入與假設!C$235,"不適用") -> 3.6 | D37: =IF(ISNUMBER(輸入與假設!D$235),輸入與假設!D$235,"不適用") -> 不適用 | E37: =IF(ISNUMBER(輸入與假設!E$235),輸入與假設!E$235,"不適用") -> 不適用 | F37: =IF(ISNUMBER(輸入與假設!F$235),輸入與假設!F$235,"不適用") -> 不適用 | G37: =IF(ISNUMBER(輸入與假設!G$235),輸入與假設!G$235,"不適用") -> 不適用 | H37: =IF(ISNUMBER(輸入與假設!H$235),輸入與假設!H$235,"不適用") -> 不適用
A38: 指引｜調整後營業利益（低） | B38: US$bn | C38: =IF(ISNUMBER(輸入與假設!C$236),輸入與假設!C$236,"不適用") -> 0.2 | D38: =IF(ISNUMBER(輸入與假設!D$236),輸入與假設!D$236,"不適用") -> 不適用 | E38: =IF(ISNUMBER(輸入與假設!E$236),輸入與假設!E$236,"不適用") -> 不適用 | F38: =IF(ISNUMBER(輸入與假設!F$236),輸入與假設!F$236,"不適用") -> 不適用 | G38: =IF(ISNUMBER(輸入與假設!G$236),輸入與假設!G$236,"不適用") -> 不適用 | H38: =IF(ISNUMBER(輸入與假設!H$236),輸入與假設!H$236,"不適用") -> 不適用
A39: 指引｜調整後營業利益（高） | B39: US$bn | C39: =IF(ISNUMBER(輸入與假設!C$237),輸入與假設!C$237,"不適用") -> 0.26 | D39: =IF(ISNUMBER(輸入與假設!D$237),輸入與假設!D$237,"不適用") -> 不適用 | E39: =IF(ISNUMBER(輸入與假設!E$237),輸入與假設!E$237,"不適用") -> 不適用 | F39: =IF(ISNUMBER(輸入與假設!F$237),輸入與假設!F$237,"不適用") -> 不適用 | G39: =IF(ISNUMBER(輸入與假設!G$237),輸入與假設!G$237,"不適用") -> 不適用 | H39: =IF(ISNUMBER(輸入與假設!H$237),輸入與假設!H$237,"不適用") -> 不適用
A40: 指引｜CapEx（毛額）（低） | B40: US$bn | C40: =IF(ISNUMBER(輸入與假設!C$238),輸入與假設!C$238,"不適用") -> 11.5 | D40: =IF(ISNUMBER(輸入與假設!D$238),輸入與假設!D$238,"不適用") -> 不適用 | E40: =IF(ISNUMBER(輸入與假設!E$238),輸入與假設!E$238,"不適用") -> 不適用 | F40: =IF(ISNUMBER(輸入與假設!F$238),輸入與假設!F$238,"不適用") -> 不適用 | G40: =IF(ISNUMBER(輸入與假設!G$238),輸入與假設!G$238,"不適用") -> 不適用 | H40: =IF(ISNUMBER(輸入與假設!H$238),輸入與假設!H$238,"不適用") -> 不適用
A41: 指引｜CapEx（毛額）（高） | B41: US$bn | C41: =IF(ISNUMBER(輸入與假設!C$239),輸入與假設!C$239,"不適用") -> 13.5 | D41: =IF(ISNUMBER(輸入與假設!D$239),輸入與假設!D$239,"不適用") -> 不適用 | E41: =IF(ISNUMBER(輸入與假設!E$239),輸入與假設!E$239,"不適用") -> 不適用 | F41: =IF(ISNUMBER(輸入與假設!F$239),輸入與假設!F$239,"不適用") -> 不適用 | G41: =IF(ISNUMBER(輸入與假設!G$239),輸入與假設!G$239,"不適用") -> 不適用 | H41: =IF(ISNUMBER(輸入與假設!H$239),輸入與假設!H$239,"不適用") -> 不適用
A42: 實際｜營收 | B42: US$bn | C42: =IF(ISNUMBER(輸入與假設!C$226),輸入與假設!C$226,"") | D42: =IF(ISNUMBER(輸入與假設!D$226),輸入與假設!D$226,"") | E42: =IF(ISNUMBER(輸入與假設!E$226),輸入與假設!E$226,"") | F42: =IF(ISNUMBER(輸入與假設!F$226),輸入與假設!F$226,"") | G42: =IF(ISNUMBER(輸入與假設!G$226),輸入與假設!G$226,"") | H42: =IF(ISNUMBER(輸入與假設!H$226),輸入與假設!H$226,"")
...

Sheet 運營_產能與收入
A1: 產能與收入 — 合約排程 vs 機房產能
A2: 兩條線獨立產生後相減：排程>容量→瓶頸（收不到）；容量>排程→剩餘產能（要靠新簽約賣掉）
A3: FY26 欄口徑：MW 為年底存量；標示「（模型期）」的收入列只含 2026 下半年——RPO 桶自 2026-06-30 起算，1H 收入已實現、不再受產能約束。1H 實際單列，兩者相加即 FY26 全年（見本頁「FY26 全年」列）。
A5: 項目 | B5: 單位 | C5: FY26 | D5: FY27 | E5: FY28 | F5: FY29 | G5: FY30 | I5: 公式／來源說明
A6: 模型期間 | C6: ="2026-07-01~12-31" -> 2026-07-01~12-31 | D6: ="2027 全年" -> 2027 全年 | E6: ="2028 全年" -> 2028 全年 | F6: ="2029 全年" -> 2029 全年 | G6: ="2030 全年" -> 2030 全年 | I6: FY26 的模型期只有下半年；1H 已實現的營收單列於下方
A7: 模型期長度（年） | C7: =輸入與假設!C$24 -> 0.5 | D7: =輸入與假設!D$24 -> 1 | E7: =輸入與假設!E$24 -> 1 | F7: =輸入與假設!F$24 -> 1 | G7: =輸入與假設!G$24 -> 1 | I7: 只用於下方三處：容量上限、電力、維護——把年率換算成該期金額
A8: （A）機房：容量上限
A9: Accepted MW（已驗收，單調不減） | B9: MW | C9: =MAX(0,輸入與假設!C$26) -> 1850 | D9: =MAX(輸入與假設!D$26,C9) -> 3100 | E9: =MAX(輸入與假設!E$26,D9) -> 4000 | F9: =MAX(輸入與假設!F$26,E9) -> 4800 | G9: =MAX(輸入與假設!G$26,F9) -> 5600 | I9: 引擎規則：不得低於前期（產能不會消失）
A10: Billable MW（上限為 Accepted） | B10: MW | C10: =MIN(MAX(0,輸入與假設!C$27),C9) -> 1700 | D10: =MIN(MAX(0,輸入與假設!D$27),D9) -> 2900 | E10: =MIN(MAX(0,輸入與假設!E$27),E9) -> 3739 | F10: =MIN(MAX(0,輸入與假設!F$27),F9) -> 4495 | G10: =MIN(MAX(0,輸入與假設!G$27),G9) -> 5250 | I10: 引擎規則：可計費不得超過已驗收
A11: 期初在役 MW | B11: MW | C11: =輸入與假設!$C$20 -> 1350 | D11: =C10 -> 1700 | E11: =D10 -> 2900 | F11: =E10 -> 3739 | G11: =F10 -> 4495 | I11: 前期期末＝本期期初
A12: 平均在役 MW（FY26 欄為下半年平均） | B12: MW | C12: =IF(輸入與假設!$C$21=1,(C11+C10)/2,C10) -> 1525 | D12: =IF(輸入與假設!$C$21=1,(D11+D10)/2,D10) -> 2300 | E12: =IF(輸入與假設!$C$21=1,(E11+E10)/2,E10) -> 3319.5 | F12: =IF(輸入與假設!$C$21=1,(F11+F10)/2,F10) -> 4117 | G12: =IF(輸入與假設!$C$21=1,(G11+G10)/2,G10) -> 4872.5 | I12: 開關在輸入頁：1＝(期初+期末)/2，0＝期末全期化
A13: 利用率 | B13: % | C13: =輸入與假設!C$28 -> 0.95 | D13: =輸入與假設!D$28 -> 0.95 | E13: =輸入與假設!E$28 -> 0.94 | F13: =輸入與假設!F$28 -> 0.93 | G13: =輸入與假設!G$28 -> 0.92
A14: 每 MW 年收入 | B14: US$bn/MW | C14: =輸入與假設!C$29 -> 0.0112 | D14: =輸入與假設!D$29 -> 0.0115 | E14: =輸入與假設!E$29 -> 0.0115 | F14: =輸入與假設!F$29 -> 0.011 | G14: =輸入與假設!G$29 -> 0.0105
A15: 容量上限（模型期最多能交付的收入） | B15: US$bn | C15: =C12*輸入與假設!C$29*輸入與假設!$C$22*輸入與假設!C$28*C7 -> 8.113 | D15: =D12*輸入與假設!D$29*輸入與假設!$C$22*輸入與假設!D$28*D7 -> 25.1275 | E15: =E12*輸入與假設!E$29*輸入與假設!$C$22*輸入與假設!E$28*E7 -> 35.883795 | F15: =F12*輸入與假設!F$29*輸入與假設!$C$22*輸入與假設!F$28*F7 -> 42.11691 | G15: =G12*輸入與假設!G$29*輸入與假設!$C$22*輸入與假設!G$28*G7 -> 47.06835 | I15: ＝平均在役 MW × 每 MW 年收入 × 利用率 × 期間係數。只看機房，不看合約
A16: （B）合約：排程 RPO
A17: 排程 RPO（模型期，依 10-Q 桶分攤） | B17: US$bn | C17: =(輸入與假設!$C$15+輸入與假設!$C$16)*(輸入與假設!C$25/輸入與假設!$C$18)*輸入與假設!$C$17 -> 13.19175 | D17: =(輸入與假設!$C$15+輸入與假設!$C$16)*(輸入與假設!D$25/輸入與假設!$C$18)*輸入與假設!$C$17 -> 26.3835 | E17: =(輸入與假設!$C$15+輸入與假設!$C$16)*(輸入與假設!E$25/輸入與假設!$C$18)*輸入與假設!$C$17 -> 25.74 | F17: =(輸入與假設!$C$15+輸入與假設!$C$16)*(輸入與假設!F$25/輸入與假設!$C$18)*輸入與假設!$C$17 -> 25.0965 | G17: =(輸入與假設!$C$15+輸入與假設!$C$16)*(輸入與假設!G$25/輸入與假設!$C$18)*輸入與假設!$C$17 -> 17.69625 | I17: ＝(6/30 RPO＋Q3 新增)×本期權重÷權重合計×五期認列比例。只看合約，不看機房
A18: （C）兩條線相減
A19: 產能瓶頸（模型期：排程 − 容量） | B19: US$bn | C19: =MAX(0,C17-C15) -> 5.07875 | D19: =MAX(0,D17-D15) -> 1.256 | E19: =MAX(0,E17-E15) -> 0 | F19: =MAX(0,F17-F15) -> 0 | G19: =MAX(0,G17-G15) -> 0 | I19: 合約有、機房沒有 → 本期收不到，且不遞延到下期（保守處理）
A20: 期初 RPO 轉換收入（模型期） | B20: US$bn | C20: =C17-C19 -> 8.113 | D20: =D17-D19 -> 25.1275 | E20: =E17-E19 -> 25.74 | F20: =F17-F19 -> 25.0965 | G20: =G17-G19 -> 17.69625 | I20: ＝排程 − 瓶頸。當瓶頸>0 時，此值恆等於容量上限
A21: 未被期初 RPO 占用的產能 | B21: US$bn | C21: =MAX(0,C15-C17) -> 0 | D21: =MAX(0,D15-D17) -> 0 | E21: =MAX(0,E15-E17) -> 10.143795 | F21: =MAX(0,F15-F17) -> 17.02041 | G21: =MAX(0,G15-G17) -> 29.3721 | I21: 容量 − 排程。機房有、期初合約沒占滿 → 要靠新簽約
A22: 新產能簽約率 | B22: % | C22: =輸入與假設!C$30 -> 1 | D22: =輸入與假設!D$30 -> 1 | E22: =輸入與假設!E$30 -> 0.9 | F22: =輸入與假設!F$30 -> 0.85 | G22: =輸入與假設!G$30 -> 0.8
A23: 新簽約收入 | B23: US$bn | C23: =C21*輸入與假設!C$30 -> 0 | D23: =D21*輸入與假設!D$30 -> 0 | E23: =E21*輸入與假設!E$30 -> 9.1294155 | F23: =F21*輸入與假設!F$30 -> 14.467348 | G23: =G21*輸入與假設!G$30 -> 23.49768 | I23: 尚未簽署的合約。FY28 起模型收入主要來自此列——8 GW 敘事的風險集中點
A24: 未售產能（浪費） | B24: US$bn | C24: =MAX(0,C15-C20-C23) -> 0 | D24: =MAX(0,D15-D20-D23) -> 0 | E24: =MAX(0,E15-E20-E23) -> 1.0143795 | F24: =MAX(0,F15-F20-F23) -> 2.5530615 | G24: =MAX(0,G15-G20-G23) -> 5.87442 | I24: 蓋好但賣不掉。Bernstein：簽約電力 74% 位於 Tier 3/4 市場
A25: 損益用算力收入（模型期＝RPO 轉換＋新簽約） | B25: US$bn | C25: =C20+C23 -> 8.113 | D25: =D20+D23 -> 25.1275 | E25: =E20+E23 -> 34.869416 | F25: =F20+F23 -> 39.563848 | G25: =G20+G23 -> 41.19393 | I25: 損益與評價頁的算力收入由此連結，確保現金與損益同一組數字
A26: 1H26 實際營收（10-Q，已實現） | B26: US$bn | C26: =輸入與假設!$C$140 -> 4.653 | D26: =0 -> 0 | E26: =0 -> 0 | F26: =0 -> 0 | G26: =0 -> 0 | I26: 2026-01-01 至 06-30 已認列營收。已實現，不受下半年產能約束，故不進入上方的瓶頸計算
A27: FY26 全年總營收（1H 實際＋模型期算力＋服務） | B27: US$bn | C27: =C26+C25+輸入與假設!C$33 -> 13.066 | D27: =D26+D25+輸入與假設!D$33 -> 26.1275 | E27: =E26+E25+輸入與假設!E$33 -> 36.669415 | F27: =F26+F25+輸入與假設!F$33 -> 42.363849 | G27: =G26+G25+輸入與假設!G$33 -> 44.99393 | I27: FY26 欄可直接對照公司全年指引 12.4–13.2；FY27 以後即為該年度總營收
A28: （D）收入 → 現金：三道折扣
A29: 客戶違約率 | B29: % | C29: =輸入與假設!C$31 -> 0.005 | D29: =輸入與假設!D$31 -> 0.01 | E29: =輸入與假設!E$31 -> 0.015 | F29: =輸入與假設!F$31 -> 0.02 | G29: =輸入與假設!G$31 -> 0.025
A30: 回收率 | B30: % | C30: =輸入與假設!C$32 -> 0.5 | D30: =輸入與假設!D$32 -> 0.5 | E30: =輸入與假設!E$32 -> 0.5 | F30: =輸入與假設!F$32 -> 0.5 | G30: =輸入與假設!G$32 -> 0.5
A31: 信用損失（期初 RPO 部分） | B31: US$bn | C31: =C20*輸入與假設!C$31*(1-輸入與假設!C$32) -> 0.0202825 | D31: =D20*輸入與假設!D$31*(1-輸入與假設!D$32) -> 0.1256375 | E31: =E20*輸入與假設!E$31*(1-輸入與假設!E$32) -> 0.19305 | F31: =F20*輸入與假設!F$31*(1-輸入與假設!F$32) -> 0.250965 | G31: =G20*輸入與假設!G$31*(1-輸入與假設!G$32) -> 0.22120313 | I31: ＝收入 × 違約率 × (1−回收率)
A32: 收現（期初 RPO 部分） | B32: US$bn | C32: =C20-C31 -> 8.0927175 | D32: =D20-D31 -> 25.001863 | E32: =E20-E31 -> 25.54695 | F32: =F20-F31 -> 24.845535 | G32: =G20-G31 -> 17.475047
A33: EBITDA 率（損益與資金共用） | B33: % | C33: =輸入與假設!C$39 -> 0.59 | D33: =輸入與假設!D$39 -> 0.605 | E33: =輸入與假設!E$39 -> 0.62 | F33: =輸入與假設!F$39 -> 0.635 | G33: =輸入與假設!G$39 -> 0.65 | I33: 起始→穩態線性爬升
A34: 模型期總營收（算力＋服務） | B34: US$bn | C34: =C25+輸入與假設!C$33 -> 8.413 | D34: =D25+輸入與假設!D$33 -> 26.1275 | E34: =E25+輸入與假設!E$33 -> 36.669415 | F34: =F25+輸入與假設!F$33 -> 42.363849 | G34: =G25+輸入與假設!G$33 -> 44.99393
A35: EBITDAR 率（EBITDA 率＋租金÷營收） | B35: % | C35: =輸入與假設!C$39+各期收支!C12/MAX(0.01,C34) -> 0.74927731 | D35: =輸入與假設!D$39+各期收支!D12/MAX(0.01,D34) -> 0.75576069 | E35: =輸入與假設!E$39+各期收支!E12/MAX(0.01,E34) -> 0.74886365 | F35: =輸入與假設!F$39+各期收支!F12/MAX(0.01,F34) -> 0.75592858 | G35: =輸入與假設!G$39+各期收支!G12/MAX(0.01,G34) -> 0.76536086 | I35: 租金前的 EBITDA 率。EBITDA 已扣租金，而資金模型把租金列在支出端，所以要加回，避免重複扣除
A36: RPO 現金（可支應資本用途） | B36: US$bn | C36: =C32*C35 -> 6.0636896 | D36: =D32*D35 -> 18.895425 | E36: =E32*E35 -> 19.131182 | F36: =F32*F35 -> 18.78145 | G36: =G32*G35 -> 13.374717 | I36: ×EBITDAR 率。租金與利息在支出頁單獨列示
A37: 新簽約現金 | B37: US$bn | C37: =C23*(1-輸入與假設!C$31*(1-輸入與假設!C$32))*C35 -> 0 | D37: =D23*(1-輸入與假設!D$31*(1-輸入與假設!D$32))*D35 -> 0 | E37: =E23*(1-輸入與假設!E$31*(1-輸入與假設!E$32))*E35 -> 6.7854123 | F37: =F23*(1-輸入與假設!F$31*(1-輸入與假設!F$32))*F35 -> 10.826919 | G37: =G23*(1-輸入與假設!G$31*(1-輸入與假設!G$32))*G35 -> 17.759402 | I37: 同樣扣信用損失、乘 EBITDAR 率
A39: 讀法：FY26（2H）與 FY27 瓶頸>0，合約多於機房；FY28 起反轉，收入愈來愈靠『新簽約收入』這一列。
A40: 把『新產能簽約率』調到 0，就能看到只靠期初 RPO 的資金缺口有多大——這是最重要的一個壓力測試。

Sheet 運營_站點
A1: 站點租賃 — 房東揭露 vs 10-Q 總額（檢驗租金路徑用）
A2: 10-Q 不揭露逐站租金；下表為房東公告的合約值（Interested-party），用來檢驗『每 MW 年租金』與模型租金路徑是否一致
A4: 站點 | B4: 房東 | C4: 契約 MW | D4: 已起租 MW | E4: 合約總值 $bn | F4: 年期 | G4: 年租金 $bn | H4: 每 MW 年租金 $m | I4: 起租時程 | J4: 10-Q 對應 | K4: 來源
A5: Helios（德州 Dickens） | B5: Galaxy (GLXY) | C5: 526 | D5: 133 | E5: 15 | F5: 15 | G5: =E5/F5 -> 1 | H5: =G5/C5*1000 -> 1.9011407 | I5: Ph I 133 MW 2026Q2 起租；Ph II 260 MW 2027H1 起；Ph III 133 MW | J5: 未交付 393 MW＝10-Q「單站上限 14.7／16 年」 | K5: Galaxy 2026-07-06：526 MW、年均租金 >$1bn、15 年＋2×5 年延長 [Interested-party]
A6: Polaris Forge 1（北達科他 Ellendale） | B6: Applied Digital (APLD) | C6: 400 | D6: 250 | E6: 11 | F6: 15 | G6: =E6/F6 -> 0.73333333 | H6: =G6/C6*1000 -> 1.8333333 | I6: 100 MW 2025Q4；150 MW 2026 年中；150 MW 2027 | J6: 大致落在未起租 35.5 內 | K6: APLD 2025-08-29／FQ2 法說：400 MW、約 $11bn、約 15 年 [Interested-party]
A7: Core Scientific 六站（Denton 等） | B7: Core Scientific (CORZ) | C7: 590 | D7: 250 | E7: 10.2 | F7: 12 | G7: =E7/F7 -> 0.85 | H7: =G7/C7*1000 -> 1.440678 | I7: 2026 年約 250 MW；2027 年初全數 590 MW | J7: 部分在帳、部分未起租；「按造價計租」355 MW 可能含部分 | K7: CORZ 2025-02-26：約 590 MW、$10.2bn、12 年；年均約 $850m [Interested-party]
A8: Kenilworth（新澤西 JV） | B8: JV（CRWV 持股 35%） | C8: 未揭露 | D8: 0 | E8: 未揭露 | F8: 15 | I8: 施工中；完工後起租 | J8: 10-Q：租金＝建造成本的一定比例，推定屬「按造價計租」355 MW | K8: 10-Q Note 3：15 年租約、租金依建造成本計；MW 與金額未揭露 [Verified]
A9: 具名站點合計 | C9: =SUM(C5:C8) -> 1516 | D9: =SUM(D5:D8) -> 633 | E9: =SUM(E5:E8) -> 36.2 | G9: =SUM(G5:G8) -> 2.5833333 | H9: =G9/C9*1000 -> 1.7040457 | K9: 加權每 MW 年租金＝具名站點的市場基準
A11: 對帳：具名站點 vs 10-Q 租賃承諾總額
A12: 10-Q 在帳租賃（未折現，已起租） | E12: 29.37 | K12: 營業 29.135＋融資 0.235 [Verified]
A13: 10-Q 未起租租賃（未折現） | E13: 35.5 | K13: 2026–2029 起租、7–16 年 [Verified]
A14: 10-Q 單站按造價計租上限 | E14: 14.7 | K14: 即 Helios 未交付 393 MW [Verified]
A15: 10-Q 已揭露租賃承諾合計 | E15: =SUM(E12:E14) -> 79.57 | K15: 另有 355 MW 按造價計租，金額未定，未含
A16: 減：具名站點合約總值 | E16: =-E9 -> -36.2
A17: ＝ 未具名站點（殘差） | E17: =E15+E16 -> 43.37 | K17: 43 座以上資料中心中未具名者（Equinix、Switch 等託管，以及其他房東）。殘差大是必然——公司不揭露逐站
A18: 殘差占 10-Q 總額 | E18: =E17/E15 -> 0.54505467
A20: 檢驗：模型租金路徑 ÷ 在役 MW vs 市場基準
A21: 項目 | B21: 單位 | C21: FY26 | D21: FY27 | E21: FY28 | F21: FY29 | G21: FY30
A22: 模型租金（在帳＋表外） | B22: US$bn | C22: =各期收支!C12 -> 1.34 | D22: =各期收支!D12 -> 3.939 | E22: =各期收支!E12 -> 4.7253548 | F22: =各期收支!F12 -> 5.123 | G22: =各期收支!G12 -> 5.1905385
A23: 平均在役 MW（Accepted） | B23: MW | C23: =(輸入與假設!C$65+輸入與假設!C$26)/2 -> 1350 | D23: =(輸入與假設!D$65+輸入與假設!D$26)/2 -> 2475 | E23: =(輸入與假設!E$65+輸入與假設!E$26)/2 -> 3550 | F23: =(輸入與假設!F$65+輸入與假設!F$26)/2 -> 4400 | G23: =(輸入與假設!G$65+輸入與假設!G$26)/2 -> 5200
A24: 模型期長度（年） | B24: 年 | C24: =輸入與假設!C$24 -> 0.5 | D24: =輸入與假設!D$24 -> 1 | E24: =輸入與假設!E$24 -> 1 | F24: =輸入與假設!F$24 -> 1 | G24: =輸入與假設!G$24 -> 1
A25: 模型每 MW 年租金 | B25: US$m/MW | C25: =C22/C24/C23*1000 -> 1.9851852 | D25: =D22/D24/D23*1000 -> 1.5915152 | E25: =E22/E24/E23*1000 -> 1.3310859 | F25: =F22/F24/F23*1000 -> 1.1643182 | G25: =G22/G24/G23*1000 -> 0.99818047 | K25: FY26 欄只含下半年租金、MW 取全年平均，略有低估
A26: 第三方租賃占比 | C26: 0.85 | K26: 其餘為自建／JV（Kenilworth、Lancaster），成本走 CapEx 或 JV 出資 [Assumed]
A27: 基準租金（MW×市場基準×占比） | B27: US$bn | C27: =C23*運營_站點!$H$9/1000*$C$26*C24 -> 0.97769624 | D27: =D23*運營_站點!$H$9/1000*$C$26*D24 -> 3.5848862 | E27: =E23*運營_站點!$H$9/1000*$C$26*E24 -> 5.141958 | F27: =F23*運營_站點!$H$9/1000*$C$26*F24 -> 6.373131 | G27: =G23*運營_站點!$H$9/1000*$C$26*G24 -> 7.5318821 | K27: 若 8 GW 多數比照 Helios／APLD／CORZ 的租金水準
A28: 差額（基準 − 模型） | B28: US$bn | C28: =C27-C22 -> -0.36230376 | D28: =D27-D22 -> -0.35411379 | E28: =E27-E22 -> 0.41660316 | F28: =F27-F22 -> 1.250131 | G28: =G27-G22 -> 2.3413437 | K28: 正值＝模型租金可能低估的金額
A29: 五期差額合計 | C29: =SUM(C28:G28) -> 3.2916603

Sheet 資產負債_既有債務
A1: 債務明細 — 10-Q Note 10（2026-06-30）逐筆＋存量利息推導
A2: 有效利率為 10-Q 揭露值（含折價攤銷，四捨五入至整數 %）。本頁算出的存量利息連回『輸入』頁，再進入支出與資金頁
A4: 工具 | B4: 類別 | C4: 到期 | D4: 有效利率 | E4: 6/30 本金 | F4: 年化利息 | I4: 備註
A5: DDTL 1.0 | B5: 追索 | C5: 2028-03 | D5: 0.15 | E5: 1.3 | F5: =D5*E5 -> 0.195 | I5: 資產層、隨客戶付款攤還 [Verified]
A6: DDTL 2.0 | B6: 追索 | C6: 2030-08 | D6: 0.11 | E6: 3.19 | F6: =D6*E6 -> 0.3509 | I6: [Verified]
A7: DDTL 2.1 | B7: 追索 | C7: 2031-03 | D7: 0.09 | E7: 3 | F7: =D7*E7 -> 0.27 | I7: [Verified]
A8: DDTL 3.0 | B8: 追索 | C8: 2030-08 | D8: 0.09 | E8: 2.215 | F8: =D8*E8 -> 0.19935 | I8: [Verified]
A9: DDTL 5.0 | B9: 追索 | C9: 2031-11 | D9: 0.09 | E9: 1.101 | F9: =D9*E9 -> 0.09909 | I9: SOFR+4.50%；額度 3.1 [Verified]
A10: 2030 Senior Notes | B10: 追索 | C10: 2030-06 | D10: 0.1 | E10: 2 | F10: =D10*E10 -> 0.2 | I10: 到期一次還本 [Verified]
A11: 2031 9.00% Senior Notes | B11: 追索 | C11: 2031-02 | D11: 0.1 | E11: 1.75 | F11: =D11*E11 -> 0.175 | I11: [Verified]
A12: 2031 9.75% Senior Notes | B12: 追索 | C12: 2031-10 | D12: 0.1 | E12: 2.75 | F12: =D12*E12 -> 0.275 | I12: 2026-04 發行 [Verified]
A13: 2032 9.625% Senior Notes | B13: 追索 | C13: 2032-07 | D13: 0.1 | E13: 1.25 | F13: =D13*E13 -> 0.125 | I13: 2026-06 發行 [Verified]
A14: 2032 EUR Senior Notes（€2.0bn） | B14: 追索 | C14: 2032-07 | D14: 0.09 | E14: 2.279 | F14: =D14*E14 -> 0.20511 | I14: 票面 8.50%；已做換匯換利避險 [Verified]
A15: 2031 可轉債 | B15: 追索 | C15: 2031-12 | D15: 0.02 | E15: 2.588 | F15: =D15*E15 -> 0.05176 | I15: [Verified]
A16: 2032 可轉債 | B16: 追索 | C16: 2032-10 | D16: 0.02 | E16: 4 | F16: =D16*E16 -> 0.08 | I16: 票面 1.75%；2026-04 發行 [Verified]
... A20: OEM 融資（非追索） | B20: 非追索 | C20: 2026-08～2028-08 | D20: 0.09 | E20: 0.882 | F20: =D20*E20 -> 0.07938 | I20: [Verified]
A21: 合計（6/30） | E21: =SUM(E5:E20) -> 35.551 | F21: =SUM(F5:F20) -> 2.99106 | I21: 應等於 10-Q 本金合計 35.551
A22: 加權有效利率 | D22: =F21/E21 -> 0.084134342 | I22: 公司 9/17 簡報：Q2 加權 8.3%、含新可轉債 pro forma 7.8%（該口徑用票面，本頁用有效利率）
A24: 9/17 期後：2033 可轉債 | D24: 0.02875 | E24: 3.7 | F24: =D24*E24 -> 0.106375 | I24: 轉換價 $97.85；2033 到期，不在五期還本表內 [Verified]
A26: 存量利息推導（本金依 10-Q 到期表遞減）
A27: 項目 | B27: 單位 | C27: FY26 | D27: FY27 | E27: FY28 | F27: FY29 | G27: FY30 | I27: 公式／來源說明
A28: 期初本金 | B28: US$bn | C28: =E21 -> 35.551 | D28: =C30 -> 31.138 | E28: =D30 -> 24.954 | F28: =E30 -> 20.538 | G28: =F30 -> 18.117 | I28: FY26 期初為 6/30 本金（模型期起點）
A29: 排程還本 | B29: US$bn | C29: =輸入與假設!C$93 -> 4.413 | D29: =輸入與假設!D$93 -> 6.184 | E29: =輸入與假設!E$93 -> 4.416 | F29: =輸入與假設!F$93 -> 2.421 | G29: =輸入與假設!G$93 -> 3.221 | I29: 10-Q 到期表
A30: 期末本金 | B30: US$bn | C30: =C28-C29 -> 31.138 | D30: =D28-D29 -> 24.954 | E30: =E28-E29 -> 20.538 | F30: =F28-F29 -> 18.117 | G30: =G28-G29 -> 14.896
A31: 平均本金 | B31: US$bn | C31: =(C28+C30)/2 -> 33.3445 | D31: =(D28+D30)/2 -> 28.046 | E31: =(E28+E30)/2 -> 22.746 | F31: =(F28+F30)/2 -> 19.3275 | G31: =(G28+G30)/2 -> 16.5065
A32: 存量債務利息 | B32: US$bn | C32: =C31*資產負債_既有債務!$D$22*輸入與假設!C$24 -> 1.4027088 | D32: =D31*資產負債_既有債務!$D$22*輸入與假設!D$24 -> 2.3596318 | E32: =E31*資產負債_既有債務!$D$22*輸入與假設!E$24 -> 1.9137197 | F32: =F31*資產負債_既有債務!$D$22*輸入與假設!F$24 -> 1.6261065 | G32: =G31*資產負債_既有債務!$D$22*輸入與假設!G$24 -> 1.3887635 | I32: ＝平均本金×加權有效利率×期間長度。限制：假設利率組合不變（實際上 15% 的 DDTL 1.0 先到期，後期利率會略降）
A33: 9/17 可轉債利息 | B33: US$bn | C33: =資產負債_既有債務!$F$24*輸入與假設!C$24 -> 0.0531875 | D33: =資產負債_既有債務!$F$24*輸入與假設!D$24 -> 0.106375 | E33: =資產負債_既有債務!$F$24*輸入與假設!E$24 -> 0.106375 | F33: =資產負債_既有債務!$F$24*輸入與假設!F$24 -> 0.106375 | G33: =資產負債_既有債務!$F$24*輸入與假設!G$24 -> 0.106375
A34: FY26 新增借款利息校準 | B34: US$bn | C34: =0.35 -> 0.35 | D34: =0 -> 0 | E34: =0 -> 0 | F34: =0 -> 0 | G34: =0 -> 0 | I34: Q3 指引 0.86–0.94／季含 Q3 新動用的 DDTL；存量推算約 0.73／季，差額×2 季≈0.35。FY27 起新增借款改由瀑布新債利息承接 [Derived]
A35: 存量利息合計（連回輸入頁） | B35: US$bn | C35: =C32+C33+C34 -> 1.8058963 | D35: =D32+D33+D34 -> 2.4660068 | E35: =E32+E33+E34 -> 2.0200947 | F35: =F32+F33+F34 -> 1.7324815 | G35: =G32+G33+G34 -> 1.4951385 | I35: v1.4 手動值為 1.8／2.7／2.3／2.0／1.8

Sheet 資產負債_新債與新股
A1: 新債與新股（類資產負債表：現金、債務、股本、槓桿）
A2: 全部為連結公式。FY26 欄的現金自 2026-06-30 起算（模型期），與 HTML『資產與負債 → 新債與新股』同口徑
A4: 項目 | B4: 單位 | C4: FY26 | D4: FY27 | E4: FY28 | F4: FY29 | G4: FY30 | I4: 公式／來源說明
A5: 現金
A6: 期初現金 | B6: US$bn | C6: =輸入與假設!$C$77 -> 5.5 | D6: =各期收支!C41 -> 2 | E6: =各期收支!D41 -> 2 | F6: =各期收支!E41 -> 2 | G6: =各期收支!F41 -> 2 | I6: FY26＝6/30 現金（模型期起點）
A7: 營運收支淨額（含 9/17 可轉債／ATM，不含瀑布） | B7: US$bn | C7: =各期收支!C71-輸入與假設!$C$77 -> -15.489544 | D7: =各期收支!D71-各期收支!C71 -> -28.606021 | E7: =各期收支!E71-各期收支!D71 -> -11.2541 | F7: =各期收支!F71-各期收支!E71 -> -5.9035121 | G7: =各期收支!G71-各期收支!F71 -> -5.9365868 | I7: ＝融資前累積現金的當期變動；負值即當期外部資金需求
A8: ＋ 瀑布：新債（額度＋資產層） | B8: US$bn | C8: =各期收支!C58 -> 12.554496 | D8: =各期收支!D58 -> 32.676842 | E8: =各期收支!E58 -> 16.840572 | F8: =各期收支!F58 -> 3.1393189 | G8: =各期收支!G58 -> 7.1787275
A9: ＋ 瀑布：高息債 | B9: US$bn | C9: =各期收支!C62 -> 0 | D9: =各期收支!D62 -> 0 | E9: =各期收支!E62 -> 0 | F9: =各期收支!F62 -> 0 | G9: =各期收支!G62 -> 0
A10: ＋ 瀑布：股權募資 | B10: US$bn | C10: =各期收支!C61 -> 0 | D10: =各期收支!D61 -> 0 | E10: =各期收支!E61 -> 0 | F10: =各期收支!F61 -> 8.6332038 | G10: =各期收支!G61 -> 5.2729553
A11: − 新融資利息（新債＋高息債） | B11: US$bn | C11: =-各期收支!C63 -> -0.56495231 | D11: =-各期收支!D63 -> -4.0708204 | E11: =-各期收支!E63 -> -5.5864719 | F11: =-各期收支!F63 -> -5.8690106 | G11: =-各期收支!G63 -> -6.515096
A12: 期末現金 | B12: US$bn | C12: =SUM(C6:C11) -> 2 | D12: =SUM(D6:D11) -> 2 | E12: =SUM(E6:E11) -> 2 | F12: =SUM(F6:F11) -> 2 | G12: =SUM(G6:G11) -> 2 | I12: 應等於『各期收支』期末累積現金（見下列驗算）
A13: 驗算：與各期收支期末現金差異 | B13: US$bn | C13: =C12-各期收支!C41 -> 0 | D13: =D12-各期收支!D41 -> 0 | E13: =E12-各期收支!E41 -> 0 | F13: =F12-各期收支!F41 -> 0 | G13: =G12-各期收支!G41 -> 0 | I13: 應為 0
A14: 債務
A15: 既有債務期初（10-Q 本金） | B15: US$bn | C15: =35.551 -> 35.551 | D15: =C17 -> 31.138 | E15: =D17 -> 24.954 | F15: =E17 -> 20.538 | G15: =F17 -> 18.117
A16: − 排程還本（模型期） | B16: US$bn | C16: =-IF(輸入與假設!$C$82=1,輸入與假設!C$93,0) -> -4.413 | D16: =-IF(輸入與假設!$C$82=1,輸入與假設!D$93,0) -> -6.184 | E16: =-IF(輸入與假設!$C$82=1,輸入與假設!E$93,0) -> -4.416 | F16: =-IF(輸入與假設!$C$82=1,輸入與假設!F$93,0) -> -2.421 | G16: =-IF(輸入與假設!$C$82=1,輸入與假設!G$93,0) -> -3.221
A17: 既有債務期末 | B17: US$bn | C17: =各期收支!C54-3.7 -> 31.138 | D17: =各期收支!D54-3.7 -> 24.954 | E17: =各期收支!E54-3.7 -> 20.538 | F17: =各期收支!F54-3.7 -> 18.117 | G17: =各期收支!G54-3.7 -> 14.896 | I17: ＝依到期表遞減（關閉攤還時維持 35.551）
A18: ＋ 9/17 可轉債（2033 到期） | B18: US$bn | C18: =3.7 -> 3.7 | D18: =3.7 -> 3.7 | E18: =3.7 -> 3.7 | F18: =3.7 -> 3.7 | G18: =3.7 -> 3.7
A19: ＋ 瀑布新債餘額 | B19: US$bn | C19: =各期收支!C67 -> 12.554496 | D19: =各期收支!D67 -> 45.231337 | E19: =各期收支!E67 -> 62.07191 | F19: =各期收支!F67 -> 65.211229 | G19: =各期收支!G67 -> 72.389956
A20: ＋ 高息債餘額 | B20: US$bn | C20: =各期收支!C69 -> 0 | D20: =各期收支!D69 -> 0 | E20: =各期收支!E69 -> 0 | F20: =各期收支!F69 -> 0 | G20: =各期收支!G69 -> 0
A21: 總債務 | B21: US$bn | C21: =SUM(C17:C20) -> 47.392496 | D21: =SUM(D17:D20) -> 73.885337 | E21: =SUM(E17:E20) -> 86.30991 | F21: =SUM(F17:F20) -> 87.028228 | G21: =SUM(G17:G20) -> 90.985956 | I21: 應等於『各期收支』期末總債務
A22: 淨負債（總債務 − 期末現金） | B22: US$bn | C22: =C21-C12 -> 45.392496 | D22: =D21-D12 -> 71.885337 | E22: =E21-E12 -> 84.30991 | F22: =F21-F12 -> 85.028228 | G22: =G21-G12 -> 88.985956
A23: 股本
A24: 基礎股數（含 ATM 上限、SBC 稀釋） | B24: bn | C24: =損益!C20 -> 0.587 | D24: =損益!D20 -> 0.59287 | E24: =損益!E20 -> 0.5987987 | F24: =損益!F20 -> 0.60478669 | G24: =損益!G20 -> 0.61083455
A25: ＋ 本期新股 | B25: bn | C25: =各期收支!C65 -> 0 | D25: =各期收支!D65 -> 0 | E25: =各期收支!E65 -> 0 | F25: =各期收支!F65 -> 0.10642903 | G25: =各期收支!G65 -> 0.065004319
A26: 總股數（期末） | B26: bn | C26: =損益!C21 -> 0.587 | D26: =損益!D21 -> 0.59287 | E26: =損益!E21 -> 0.5987987 | F26: =損益!F21 -> 0.71121572 | G26: =損益!G21 -> 0.7822679 | I26: ＝基礎股數＋累計新股
A27: 槓桿
A28: 期末 backlog | B28: US$bn | C28: =各期收支!C53 -> 115.50825 | D28: =各期收支!D53 -> 89.12475 | E28: =各期收支!E53 -> 99.902412 | F28: =各期收支!F53 -> 87.028228 | G28: =各期收支!G53 -> 90.985956
A29: 債務上限（債務／backlog × 期末 backlog） | B29: US$bn | C29: =各期收支!C55 -> 115.50825 | D29: =各期收支!D55 -> 89.12475 | E29: =各期收支!E55 -> 99.902412 | F29: =各期收支!F55 -> 87.028228 | G29: =各期收支!G55 -> 90.985956
A30: 總債務 ÷ 期末 backlog | B30: x | C30: =C21/MAX(0.01,C28) -> 0.41029533 | D30: =D21/MAX(0.01,D28) -> 0.82901032 | E30: =E21/MAX(0.01,E28) -> 0.8639422 | F30: =F21/MAX(0.01,F28) -> 1 | G30: =G21/MAX(0.01,G28) -> 1 | I30: 高息債不受 backlog 上限約束
A31: 總債務 ÷ EBITDA（年化） | B31: x | C31: =C21/MAX(0.01,損益!C19/輸入與假設!C$24) -> 4.773937 | D31: =D21/MAX(0.01,損益!D19/輸入與假設!D$24) -> 4.6741757 | E31: =E21/MAX(0.01,損益!E19/輸入與假設!E$24) -> 3.796339 | F31: =F21/MAX(0.01,損益!F19/輸入與假設!F$24) -> 3.2351246 | G31: =G21/MAX(0.01,損益!G19/輸入與假設!G$24) -> 3.1110506 | I31: FY26 模型期 EBITDA 以半年×2 年化

Sheet 資產負債_租賃承諾
A1: 租賃與承諾 — 10-Q（2026-06-30）原始揭露
A2: 本頁為硬編碼的申報數字（藍字），支出與資金頁的租金與還本列由此而來
A4: 在帳租賃到期表（未折現）
A5: 項目 | B5: 單位 | C5: 2026 下半 | D5: 2027 | E5: 2028 | F5: 2029 | G5: 2030 | H5: 其後
A6: 營業租賃付款 | B6: US$bn | C6: 1.028 | D6: 2.116 | E6: 2.306 | F6: 2.373 | G6: 2.289 | H6: 19.023
A7: 融資租賃付款 | B7: US$bn | C7: 0.012 | D7: 0.223 | E7: 0 | F7: 0 | G7: 0 | H7: 0
A8: 合計（＝支出頁「在帳現金租金」） | C8: =SUM(C6:C7) -> 1.04 | D8: =SUM(D6:D7) -> 2.339 | E8: =SUM(E6:E7) -> 2.306 | F8: =SUM(F6:F7) -> 2.373 | G8: =SUM(G6:G7) -> 2.289 | H8: =SUM(H6:H7) -> 19.023 | I8: 營業租賃負債現值 16.319、融資租賃 0.221；加權剩餘租期 12 年、折現率 10% [Verified]
A10: 債務本金到期表
A11: 項目 | B11: 單位 | C11: 2026 下半 | D11: 2027 | E11: 2028 | F11: 2029 | G11: 2030 | H11: 其後
A12: 本金（＝支出頁「排程還本」） | B12: US$bn | C12: 4.413 | D12: 6.184 | E12: 4.416 | F12: 2.421 | G12: 3.221 | H12: 14.896 | I12: 本金合計 35.551（DDTL 13.6、票據 16.6、OEM 5.1 等）[Verified]
A13: 合計 | C13: =SUM(C12:H12) -> 35.551
A15: 表外與契約性承諾（未入表）
A16: 項目 | B16: 單位 | C16: 金額 | D16: 時程 | E16: 入表？ | F16: 模型位置
A17: 未起租租賃（未折現） | B17: US$bn | C17: 35.5 | D17: 2026–2029 起租，7–16 年 | E17: 否 | F17: 表外現金租金
A18: 單站按造價計租，上限 | B18: US$bn | C18: 14.7 | D18: 393 MW 未交付，16 年 | E18: 否 | F18: 表外現金租金
A19: 按造價計租，355 MW | B19: US$bn | C19: 未定 | D19: 2026–2028 分期，金額未定 | E19: 否 | F19: 表外現金租金
A20: 承租人自備設備承諾 | B20: US$bn | C20: 1.2 | D20: 0.5–1.2，分期至 2028 | E20: 否 | F20: 併入毛 CapEx
A21: JV 出資承諾 | B21: US$bn | C21: 1.7 | D21: 已付 0.55 | E21: 否 | F21: JV／策略投資出資
A22: VIE 最大損失暴露 | B22: US$bn | C22: 0.108 | D22: — | E22: 否 | F22: 不另列
A23: 可用信用額度（RCF＋DDTL 未動用） | B23: US$bn | C23: 10.014 | D23: DDTL 4.0 可動用至 2027-06 | E23: 否（來源） | F23: 選用開關
A24: 已揭露金額之承諾合計（未起租＋單站上限） | C24: =C17+C18 -> 50.2
A25: 模型表外租金五期合計 | C25: =SUM(各期收支!C11:G11) -> 9.9708933
A26: 模型表外租金尾端（FY30×12 年） | C26: =各期收支!G11*12 -> 34.818462
A27: 模型路徑合計 ÷ 已承諾（≥0.8 為合理） | C27: =(C25+C26)/C24 -> 0.89221822 | I27: 8 GW 路徑所需新租約多數尚未簽署，路徑高於已承諾屬假設而非錯誤

Sheet 損益
A1: 損益（類損益表）— 與資金模型同一組收入
A2: 算力收入、Cash CapEx、利息皆由前面分頁連結而來；改資金假設，此頁會跟著動
A4: 項目 | B4: 單位 | C4: FY26 | D4: FY27 | E4: FY28 | F4: FY29 | G4: FY30 | I4: 公式／來源說明
A5: 損益表
A6: 算力收入 | B6: US$bn | C6: =運營_產能與收入!C25 -> 8.113 | D6: =運營_產能與收入!D25 -> 25.1275 | E6: =運營_產能與收入!E25 -> 34.869416 | F6: =運營_產能與收入!F25 -> 39.563848 | G6: =運營_產能與收入!G25 -> 41.19393 | I6: ＝RPO 轉換＋新簽約
A7: 非算力服務 | B7: US$bn | C7: =輸入與假設!C$33 -> 0.3 | D7: =輸入與假設!D$33 -> 1 | E7: =輸入與假設!E$33 -> 1.8 | F7: =輸入與假設!F$33 -> 2.8 | G7: =輸入與假設!G$33 -> 3.8
A8: 總營收 | B8: US$bn | C8: =C6+C7 -> 8.413 | D8: =D6+D7 -> 26.1275 | E8: =E6+E7 -> 36.669415 | F8: =F6+F7 -> 42.363849 | G8: =G6+G7 -> 44.99393
A9: EBITDA 率 | B9: % | C9: =輸入與假設!C$39 -> 0.59 | D9: =輸入與假設!D$39 -> 0.605 | E9: =輸入與假設!E$39 -> 0.62 | F9: =輸入與假設!F$39 -> 0.635 | G9: =輸入與假設!G$39 -> 0.65
A10: 營業利益（EBIT） | B10: US$bn | C10: =C8*輸入與假設!C$39-輸入與假設!C$74 -> 0.20083667 | D10: =D8*輸入與假設!D$39-輸入與假設!D$74 -> 1.3505542 | E10: =E8*輸入與假設!E$39-輸入與假設!E$74 -> 2.6330376 | F10: =F8*輸入與假設!F$39-輸入與假設!F$74 -> 2.0815438 | G10: =G8*輸入與假設!G$39-輸入與假設!G$74 -> 0.19072117 | I10: ＝營收×EBITDA 率 − 車隊 D&A
A11: 利息（含瀑布新債） | B11: US$bn | C11: =各期收支!C17 -> 2.3708486 | D11: =各期收支!D17 -> 6.5368271 | E11: =各期收支!E17 -> 7.6065666 | F11: =各期收支!F17 -> 7.6014921 | G11: =各期收支!G17 -> 8.0102346
A12: 稅前損益 | B12: US$bn | C12: =C10-C11 -> -2.1700119 | D12: =D10-D11 -> -5.186273 | E12: =E10-E11 -> -4.973529 | F12: =F10-F11 -> -5.5199483 | G12: =G10-G11 -> -7.8195134
A13: NOL 期初餘額 | B13: US$bn | C13: =輸入與假設!$C$105 -> 4 | D13: =C15 -> 6.1700119 | E13: =D15 -> 11.356285 | F13: =E15 -> 16.329814 | G13: =F15 -> 21.849762 | I13: 6/30 累積虧損約 4.0
A14: 本期動用 NOL | B14: US$bn | C14: =MIN(C13,MAX(0,C12)*0.8) -> 0 | D14: =MIN(D13,MAX(0,D12)*0.8) -> 0 | E14: =MIN(E13,MAX(0,E12)*0.8) -> 0 | F14: =MIN(F13,MAX(0,F12)*0.8) -> 0 | G14: =MIN(G13,MAX(0,G12)*0.8) -> 0 | I14: 美國規定：抵扣上限為應稅所得 80%
A15: NOL 期末餘額 | B15: US$bn | C15: =C13-C14+MAX(0,-C12) -> 6.1700119 | D15: =D13-D14+MAX(0,-D12) -> 11.356285 | E15: =E13-E14+MAX(0,-E12) -> 16.329814 | F15: =F13-F14+MAX(0,-F12) -> 21.849762 | G15: =G13-G14+MAX(0,-G12) -> 29.669276
A16: 所得稅 | B16: US$bn | C16: =MAX(0,C12-C14)*輸入與假設!$C$104 -> 0 | D16: =MAX(0,D12-D14)*輸入與假設!$C$104 -> 0 | E16: =MAX(0,E12-E14)*輸入與假設!$C$104 -> 0 | F16: =MAX(0,F12-F14)*輸入與假設!$C$104 -> 0 | G16: =MAX(0,G12-G14)*輸入與假設!$C$104 -> 0 | I16: 虧損年不認列稅盾（與公司評價備抵一致）
A17: 淨利 | B17: US$bn | C17: =C12-C16 -> -2.1700119 | D17: =D12-D16 -> -5.186273 | E17: =E12-E16 -> -4.973529 | F17: =F12-F16 -> -5.5199483 | G17: =G12-G16 -> -7.8195134
A18: D&A | B18: US$bn | C18: =輸入與假設!C$74 -> 4.7628333 | D18: =輸入與假設!D$74 -> 14.456583 | E18: =輸入與假設!E$74 -> 20.102 | F18: =輸入與假設!F$74 -> 24.8195 | G18: =輸入與假設!G$74 -> 29.055333 | I18: 車隊折舊，見輸入頁
A19: EBITDA | B19: US$bn | C19: =C10+C18 -> 4.96367 | D19: =D10+D18 -> 15.807137 | E19: =E10+E18 -> 22.735038 | F19: =F10+F18 -> 26.901044 | G19: =G10+G18 -> 29.246054
A20: 基礎股數（每年 +SBC 稀釋） | B20: bn | C20: =輸入與假設!$C$99 -> 0.587 | D20: =C20*(1+輸入與假設!$C$112) -> 0.59287 | E20: =D20*(1+輸入與假設!$C$112) -> 0.5987987 | F20: =E20*(1+輸入與假設!$C$112) -> 0.60478669 | G20: =F20*(1+輸入與假設!$C$112) -> 0.61083455 | I20: FY26＝含 ATM 上限 0.587；之後每年 ×(1＋股數年增)
A21: 股數（含瀑布新股） | B21: bn | C21: =C20+各期收支!C66 -> 0.587 | D21: =D20+各期收支!D66 -> 0.59287 | E21: =E20+各期收支!E66 -> 0.5987987 | F21: =F20+各期收支!F66 -> 0.71121572 | G21: =G20+各期收支!G66 -> 0.7822679 | I21: ＝基礎股數＋累計瀑布新股
A22: 每股盈餘（EPS，模型期） | B22: US$ | C22: =C17/C21 -> -3.6967835 | D22: =D17/D21 -> -8.7477406 | E22: =E17/E21 -> -8.3058447 | F22: =F17/F21 -> -7.7612855 | G22: =G17/G21 -> -9.9959532 | I22: FY26 欄只含下半年；全年口徑見下方
A24: 損益表（全年口徑；FY26＝1H 實際＋下半年模型；與 HTML 損益簡表一致）
A25: 1H26 實際營收（已實現） | B25: US$bn | C25: =輸入與假設!$C$140 -> 4.653 | D25: =0 -> 0 | E25: =0 -> 0 | F25: =0 -> 0 | G25: =0 -> 0
A26: 全年總營收 | B26: US$bn | C26: =C25+C8 -> 13.066 | D26: =D25+D8 -> 26.1275 | E26: =E25+E8 -> 36.669415 | F26: =F25+F8 -> 42.363849 | G26: =G25+G8 -> 44.99393 | I26: FY26 可對照指引 12.4–13.2
A27: 營收 YoY | B27: % | C27: =C26/5.131-1 -> 1.5464822 | D27: =D26/C26-1 -> 0.99965559 | E27: =E26/D26-1 -> 0.40347969 | F27: =F26/E26-1 -> 0.15529108 | G27: =G26/F26-1 -> 0.062083158 | I27: FY25 實際 5.131
A28: 全年 GAAP 營業利益 | B28: US$bn | C28: =輸入與假設!$C$141+C10 -> 0.0078366667 | D28: =D10 -> 1.3505542 | E28: =E10 -> 2.6330376 | F28: =F10 -> 2.0815438 | G28: =G10 -> 0.19072117
A29: 營利率 | B29: % | C29: =C28/C26 -> 0.0005997755 | D29: =D28/D26 -> 0.051690907 | E29: =E28/E26 -> 0.071804734 | F29: =F28/F26 -> 0.049134908 | G29: =G28/G26 -> 0.0042388199
A30: 全年 D&A | B30: US$bn | C30: =輸入與假設!$C$144+C18 -> 7.3028333 | D30: =D18 -> 14.456583 | E30: =E18 -> 20.102 | F30: =F18 -> 24.8195 | G30: =G18 -> 29.055333 | I30: 1H 實際 2.540
A31: 全年 EBITDA | B31: US$bn | C31: =C28+C30 -> 7.31067 | D31: =D28+D30 -> 15.807137 | E31: =E28+E30 -> 22.735038 | F31: =F28+F30 -> 26.901044 | G31: =G28+G30 -> 29.246054
A32: 全年利息（含瀑布新債） | B32: US$bn | C32: =輸入與假設!$C$138+C11 -> 3.5468486 | D32: =D11 -> 6.5368271 | E32: =E11 -> 7.6065666 | F32: =F11 -> 7.6014921 | G32: =G11 -> 8.0102346 | I32: FY27 起瀑布新債利息（9%）與新股同時影響 EPS
A33: 全年淨利 | B33: US$bn | C33: =輸入與假設!$C$142+C17 -> -3.5360119 | D33: =D17 -> -5.186273 | E33: =E17 -> -4.973529 | F33: =F17 -> -5.5199483 | G33: =G17 -> -7.8195134
A34: 淨利率 | B34: % | C34: =C33/C26 -> -0.27062697 | D34: =D33/D26 -> -0.19849863 | E34: =E33/E26 -> -0.13563153 | F34: =F33/F26 -> -0.13029856 | G34: =G33/G26 -> -0.17379041
A35: 全年 GAAP EPS | B35: US$ | C35: =輸入與假設!$C$146+C17/C21 -> -6.2267835 | D35: =D17/D21 -> -8.7477406 | E35: =E17/E21 -> -8.3058447 | F35: =F17/F21 -> -7.7612855 | G35: =G17/G21 -> -9.9959532 | I35: FY26＝1H 實際 EPS −2.53＋下半年淨利÷股數
